Workbook

Sheet ROI
A1: Year | B1: Month | C1: Month Num | D1: Contact Forms | E1: RAQ | F1: CTM
A2: =IF(ISBLANK(C2),,2026) -> 2026 | B2: January | C2: 1 | D2: =SUMIFS('Yelp Sandbox Forms (2)'!M:M,'Yelp Sandbox Forms (2)'!T:T,ROI!A2,'Yelp Sandbox Forms (2)'!S:S,ROI!C2,'Yelp Sandbox Forms (2)'!Q:Q,1) -> 0 | E2: =SUMIFS('YELP RAQ - Lead Tracking (2)'!J:J,'YELP RAQ - Lead Tracking (2)'!AA:AA,ROI!A2,'YELP RAQ - Lead Tracking (2)'!Z:Z,ROI!C2) -> 0 | F2: =SUMIFS('Yelp CTM'!C:C,'Yelp CTM'!B:B,ROI!C2,'Yelp CTM'!A:A,ROI!A2) -> 2167
A3: =IF(ISBLANK(C3),,2026) -> 2026 | B3: February | C3: 2 | D3: =SUMIFS('Yelp Sandbox Forms (2)'!M:M,'Yelp Sandbox Forms (2)'!T:T,ROI!A3,'Yelp Sandbox Forms (2)'!S:S,ROI!C3,'Yelp Sandbox Forms (2)'!Q:Q,1) -> 29823 | E3: =SUMIFS('YELP RAQ - Lead Tracking (2)'!J:J,'YELP RAQ - Lead Tracking (2)'!AA:AA,ROI!A3,'YELP RAQ - Lead Tracking (2)'!Z:Z,ROI!C3) -> 0 | F3: =SUMIFS('Yelp CTM'!C:C,'Yelp CTM'!B:B,ROI!C3,'Yelp CTM'!A:A,ROI!A3) -> 1814
A4: =IF(ISBLANK(C4),,2026) -> 2026 | B4: March | C4: 3 | D4: =SUMIFS('Yelp Sandbox Forms (2)'!M:M,'Yelp Sandbox Forms (2)'!T:T,ROI!A4,'Yelp Sandbox Forms (2)'!S:S,ROI!C4,'Yelp Sandbox Forms (2)'!Q:Q,1) -> 0 | E4: =SUMIFS('YELP RAQ - Lead Tracking (2)'!J:J,'YELP RAQ - Lead Tracking (2)'!AA:AA,ROI!A4,'YELP RAQ - Lead Tracking (2)'!Z:Z,ROI!C4) -> 2935 | F4: =SUMIFS('Yelp CTM'!C:C,'Yelp CTM'!B:B,ROI!C4,'Yelp CTM'!A:A,ROI!A4) -> 755
A5: =IF(ISBLANK(C5),,2026) -> 2026 | B5: April | C5: 4 | D5: =SUMIFS('Yelp Sandbox Forms (2)'!M:M,'Yelp Sandbox Forms (2)'!T:T,ROI!A5,'Yelp Sandbox Forms (2)'!S:S,ROI!C5,'Yelp Sandbox Forms (2)'!Q:Q,1) -> 0 | E5: =SUMIFS('YELP RAQ - Lead Tracking (2)'!J:J,'YELP RAQ - Lead Tracking (2)'!AA:AA,ROI!A5,'YELP RAQ - Lead Tracking (2)'!Z:Z,ROI!C5) -> 14277 | F5: =SUMIFS('Yelp CTM'!C:C,'Yelp CTM'!B:B,ROI!C5,'Yelp CTM'!A:A,ROI!A5) -> 26821
A6: =IF(ISBLANK(C6),,2026) -> 2026 | B6: May | C6: 5 | D6: =SUMIFS('Yelp Sandbox Forms (2)'!M:M,'Yelp Sandbox Forms (2)'!T:T,ROI!A6,'Yelp Sandbox Forms (2)'!S:S,ROI!C6,'Yelp Sandbox Forms (2)'!Q:Q,1) -> 0 | E6: =SUMIFS('YELP RAQ - Lead Tracking (2)'!J:J,'YELP RAQ - Lead Tracking (2)'!AA:AA,ROI!A6,'YELP RAQ - Lead Tracking (2)'!Z:Z,ROI!C6) -> 4924 | F6: =SUMIFS('Yelp CTM'!C:C,'Yelp CTM'!B:B,ROI!C6,'Yelp CTM'!A:A,ROI!A6) -> 8274
A7: =IF(ISBLANK(C7),,2026) -> 2026 | B7: June | C7: 6 | D7: =SUMIFS('Yelp Sandbox Forms (2)'!M:M,'Yelp Sandbox Forms (2)'!T:T,ROI!A7,'Yelp Sandbox Forms (2)'!S:S,ROI!C7,'Yelp Sandbox Forms (2)'!Q:Q,1) -> 0 | E7: =SUMIFS('YELP RAQ - Lead Tracking (2)'!J:J,'YELP RAQ - Lead Tracking (2)'!AA:AA,ROI!A7,'YELP RAQ - Lead Tracking (2)'!Z:Z,ROI!C7) -> 0 | F7: =SUMIFS('Yelp CTM'!C:C,'Yelp CTM'!B:B,ROI!C7,'Yelp CTM'!A:A,ROI!A7) -> 0
A8: =IF(ISBLANK(C8),,2026) -> 2026 | B8: July | C8: 7 | D8: =SUMIFS('Yelp Sandbox Forms (2)'!M:M,'Yelp Sandbox Forms (2)'!T:T,ROI!A8,'Yelp Sandbox Forms (2)'!S:S,ROI!C8,'Yelp Sandbox Forms (2)'!Q:Q,1) -> 0 | E8: =SUMIFS('YELP RAQ - Lead Tracking (2)'!J:J,'YELP RAQ - Lead Tracking (2)'!AA:AA,ROI!A8,'YELP RAQ - Lead Tracking (2)'!Z:Z,ROI!C8) -> 0 | F8: =SUMIFS('Yelp CTM'!C:C,'Yelp CTM'!B:B,ROI!C8,'Yelp CTM'!A:A,ROI!A8) -> 0
A9: =IF(ISBLANK(C9),,2026) -> 2026 | B9: August | C9: 8 | D9: =SUMIFS('Yelp Sandbox Forms (2)'!M:M,'Yelp Sandbox Forms (2)'!T:T,ROI!A9,'Yelp Sandbox Forms (2)'!S:S,ROI!C9,'Yelp Sandbox Forms (2)'!Q:Q,1) -> 0 | E9: =SUMIFS('YELP RAQ - Lead Tracking (2)'!J:J,'YELP RAQ - Lead Tracking (2)'!AA:AA,ROI!A9,'YELP RAQ - Lead Tracking (2)'!Z:Z,ROI!C9) -> 0 | F9: =SUMIFS('Yelp CTM'!C:C,'Yelp CTM'!B:B,ROI!C9,'Yelp CTM'!A:A,ROI!A9) -> 0
A10: =IF(ISBLANK(C10),,2026) -> 2026 | B10: September | C10: 9 | D10: =SUMIFS('Yelp Sandbox Forms (2)'!M:M,'Yelp Sandbox Forms (2)'!T:T,ROI!A10,'Yelp Sandbox Forms (2)'!S:S,ROI!C10,'Yelp Sandbox Forms (2)'!Q:Q,1) -> 0 | E10: =SUMIFS('YELP RAQ - Lead Tracking (2)'!J:J,'YELP RAQ - Lead Tracking (2)'!AA:AA,ROI!A10,'YELP RAQ - Lead Tracking (2)'!Z:Z,ROI!C10) -> 0 | F10: =SUMIFS('Yelp CTM'!C:C,'Yelp CTM'!B:B,ROI!C10,'Yelp CTM'!A:A,ROI!A10) -> 0
A11: =IF(ISBLANK(C11),,2026) -> 2026 | B11: October | C11: 10 | D11: =SUMIFS('Yelp Sandbox Forms (2)'!M:M,'Yelp Sandbox Forms (2)'!T:T,ROI!A11,'Yelp Sandbox Forms (2)'!S:S,ROI!C11,'Yelp Sandbox Forms (2)'!Q:Q,1) -> 0 | E11: =SUMIFS('YELP RAQ - Lead Tracking (2)'!J:J,'YELP RAQ - Lead Tracking (2)'!AA:AA,ROI!A11,'YELP RAQ - Lead Tracking (2)'!Z:Z,ROI!C11) -> 0 | F11: =SUMIFS('Yelp CTM'!C:C,'Yelp CTM'!B:B,ROI!C11,'Yelp CTM'!A:A,ROI!A11) -> 0
A12: =IF(ISBLANK(C12),,2026) -> 2026 | B12: November | C12: 11 | D12: =SUMIFS('Yelp Sandbox Forms (2)'!M:M,'Yelp Sandbox Forms (2)'!T:T,ROI!A12,'Yelp Sandbox Forms (2)'!S:S,ROI!C12,'Yelp Sandbox Forms (2)'!Q:Q,1) -> 0 | E12: =SUMIFS('YELP RAQ - Lead Tracking (2)'!J:J,'YELP RAQ - Lead Tracking (2)'!AA:AA,ROI!A12,'YELP RAQ - Lead Tracking (2)'!Z:Z,ROI!C12) -> 0 | F12: =SUMIFS('Yelp CTM'!C:C,'Yelp CTM'!B:B,ROI!C12,'Yelp CTM'!A:A,ROI!A12) -> 0
A13: =IF(ISBLANK(C13),,2026) -> 2026 | B13: December | C13: 12 | D13: =SUMIFS('Yelp Sandbox Forms (2)'!M:M,'Yelp Sandbox Forms (2)'!T:T,ROI!A13,'Yelp Sandbox Forms (2)'!S:S,ROI!C13,'Yelp Sandbox Forms (2)'!Q:Q,1) -> 0 | E13: =SUMIFS('YELP RAQ - Lead Tracking (2)'!J:J,'YELP RAQ - Lead Tracking (2)'!AA:AA,ROI!A13,'YELP RAQ - Lead Tracking (2)'!Z:Z,ROI!C13) -> 0 | F13: =SUMIFS('Yelp CTM'!C:C,'Yelp CTM'!B:B,ROI!C13,'Yelp CTM'!A:A,ROI!A13) -> 0
A14: Total | D14: =SUM(D2:D13) -> 29823 | E14: =SUM(E2:E13) -> 22136 | F14: =SUM(F2:F13) -> 39831 | G14: =SUM(D14:F14) -> 91790

Sheet Yelp Sandbox Forms (2)
A1: Phone Number | B1: Date of Message | C1: Message Contents | D1: Message Source | E1: IM Lead | F1: Potential Sales Lead | G1: Customer ID | H1: Subscription is Active | I1: Customer record start date | J1: Customer unix cxl date | K1: Subscription Id | L1: Completed Initial | M1: Contract Value | N1: Subscription Start Date | O1: Subscription unix cxl date | P1: Service Type | Q1: Sale | R1: Corn Id | S1: Custom | T1: Custom.1
A2: 2014760436 | B2: 46073.501 | C2: {_x000D_ "id": 4037316584,_x000D_ "sid": "log-call-no-answer-230fb629cb51652d",_x000D_ "account_id": 441826,_x000D_ "name": "test mc testy",_x000D_ "cnam": "test mc testy",_x000D_ "search": "",_x000D_ "referrer": "",_x000D_ "visitor_sid": "",_x000D_ "location": "",_x000D_ "source": "Sandbox",_x000D_ "source_id": 1814974,_x000D_ "source_sid": "TSOF6FC2D2594D22C5288F2F91D669A9D5B9BE7FEE3C6EF44F4A9EA1A63913ECD83",_x000D_ "tgid": 5681974,_x000D_ "likelihood": null,_x000D_ "duration": 0,_x000D_ "direction": "form",_x000D_ "talk_time": 0,_x000D_ "ring_time": 0,_x000D_ "hold_time": 0,_x000D_ "wait_time": 0,_x000D_ "parent_id": null,_x000D_ "email": "chris.keenan@fox-pest.com",_x000D_ "street": null,_x000D_ "city": null,_x000D_ "state": null,_x000D_ "country": null,_x000D_ "postal_code": "07642",_x000D_ "called_at": "2026-02-20 06:02 AM -06:00",_x000D_ "unix_time": 1771592535,_x000D_ "tracking_number_id": 3476065,_x000D_ "tracking_number_sid": "TPNC3C4B23C348AEC2EE54EFD301979CD2EFFBA32881B159867D3F4ED59E6F0B56367EFF2993536685F",_x000D_ "tracking_number": "\u002B14352541043",_x000D_ "tracking_label": "Testing Number",_x000D_ "dial_status": "no-answer",_x000D_ "is_new_caller": true,_x000D_ "indexed_at": 1.7715931E+09,_x000D_ "agent_insights": false,_x000D_ "duration_period": {_x000D_ "gte": 1771592535000,_x000D_ "lte": 1771592535000_x000D_ },_x000D_ "inbound_rate_center": {_x000D_ "country": "US",_x000D_ "prefix": "1",_x000D_ "tollfree": false_x000D_ },_x000D_ "business_number": null,_x000D_ "business_label": null,_x000D_ "receiving_number_id": null,_x000D_ "receiving_number_sid": null,_x000D_ "billed_amount": 0,_x000D_ "billed_at": "0001-01-01T00:00:00",_x000D_ "excluded": false,_x000D_ "redacted": false,_x000D_ "tracking_number_format": "(435) 254-1043",_x000D_ "business_number_format": null,_x000D_ "alternative_number": "2014760436",_x000D_ "tracking_number_bare": "4352541043",_x000D_ "caller_number_format": "(201) 476-0436",_x000D_ "caller_number_complete": "\u002B12014760436",_x000D_ "caller_number_bare": "2014760436",_x000D_ "caller_number": "\u002B12014760436",_x000D_ "caller_number_split": [_x000D_ "1",_x000D_ "201",_x000D_ "476",_x000D_ "0436"_x000D_ ],_x000D_ "contact_number": "\u002B12014760436",_x000D_ "visitor": false,_x000D_ "call_path": [_x000D_ {_x000D_ "route_name": "_OnHangup_CallSync",_x000D_ "route_id": "640990",_x000D_ "route_type": "RoutingRule",_x000D_ "started_at": "2026-02-20T06:02:16Z"_x000D_ }_x000D_ ],_x000D_ "left_talk_time": 0,_x000D_ "right_talk_time": 0,_x000D_ "transfers": [],_x000D_ "call_status": "completed",_x000D_ "status": "completed",_x000D_ "spotted": [],_x000D_ "salesforce": {},_x000D_ "audio": null,_x000D_ "is_s3_link": false,_x000D_ "callbacks": [],_x000D_ "emails": [],_x000D_ "day": "Friday",_x000D_ "month": "February",_x000D_ "hour": "06AM",_x000D_ "paid": {_x000D_ "source": null,_x000D_ "medium": null_x000D_ },_x000D_ "ga": {_x000D_ "cid": "441826.4037316584",_x000D_ "ga4": []_x000D_ },_x000D_ "tag_list": [],_x000D_ "latitude": 41.0369,_x000D_ "longitude": -74.0405,_x000D_ "extended_lookup_on": true,_x000D_ "form": {_x000D_ "number_to_call": "log-call-no-answer-436038320fcfa469",_x000D_ "customer_number_to_dial": "\u002B12014760436",_x000D_ "name": "test mc testy",_x000D_ "email": "chris.keenan@fox-pest.com",_x000D_ "trackback_id": "trackback-441826.1771592535.2455",_x000D_ "form_id": 213071,_x000D_ "form_name": "Contact Us",_x000D_ "custom": [_x000D_ {_x000D_ "label": "Referral Source",_x000D_ "value": "",_x000D_ "id": "referral_source"_x000D_ },_x000D_ {_x000D_ "label": "UTM Source",_x000D_ "value": "",_x000D_ "id": "utm_source"_x000D_ },_x000D_ {_x000D_ "label": "UTM Medium",_x000D_ "value": "",_x000D_ "id": "utm_medium"_x000D_ },_x000D_ {_x000D_ "label": "UTM Campaign",_x000D_ "value": "",_x000D_ "id": "utm_campaign"_x000D_ },_x000D_ {_x000D_ "label": "UTM Term",_x000D_ "value": "",_x000D_ "id": "utm_term"_x000D_ },_x000D_ {_x000D_ "label": "UTM Content",_x000D_ "value": "",_x000D_ "id": "utm_content"_x000D_ }_x000D_ ]_x000D_ },_x000D_ "legs": [],_x000D_ "touchpoints": null,_x000D_ "last_touch": null,_x000D_ "geo": {_x000D_ "lon": -74.0405,_x000D_ "lat": 41.0369_x000D_ },_x000D_ "timestamp": "0001-01-01T00:00:00"_x000D_ } | E2: 0 | F2: 1 | Q2: 0 | R2: 4037316584 | S2: 2 | T2: 2026
A3: 2015552012 | B3: 46073.116 | C3: {_x000D_ "id": 4037107502,_x000D_ "sid": "log-call-no-answer-2fec2fe1231a4499",_x000D_ "account_id": 441826,_x000D_ "name": "Shirley Desimone",_x000D_ "cnam": "Shirley Desimone",_x000D_ "search": "",_x000D_ "referrer": "",_x000D_ "visitor_sid": "",_x000D_ "location": "",_x000D_ "source": "Sandbox",_x000D_ "source_id": 1814974,_x000D_ "source_sid": "TSOF6FC2D2594D22C5288F2F91D669A9D5B9BE7FEE3C6EF44F4A9EA1A63913ECD83",_x000D_ "tgid": 5681974,_x000D_ "likelihood": null,_x000D_ "duration": 0,_x000D_ "direction": "form",_x000D_ "talk_time": 0,_x000D_ "ring_time": 0,_x000D_ "hold_time": 0,_x000D_ "wait_time": 0,_x000D_ "parent_id": null,_x000D_ "email": "shirleydesimone.mkt@gmail.com",_x000D_ "street": null,_x000D_ "city": null,_x000D_ "state": null,_x000D_ "country": null,_x000D_ "postal_code": null,_x000D_ "called_at": "2026-02-19 08:47 PM -06:00",_x000D_ "unix_time": 1771559249,_x000D_ "tracking_number_id": 3476065,_x000D_ "tracking_number_sid": "TPNC3C4B23C348AEC2EE54EFD301979CD2EFFBA32881B159867D3F4ED59E6F0B56367EFF2993536685F",_x000D_ "tracking_number": "\u002B14352541043",_x000D_ "tracking_label": "Testing Number",_x000D_ "dial_status": "no-answer",_x000D_ "is_new_caller": true,_x000D_ "indexed_at": 1.7715598E+09,_x000D_ "agent_insights": false,_x000D_ "duration_period": {_x000D_ "gte": 1771559249000,_x000D_ "lte": 1771559249000_x000D_ },_x000D_ "inbound_rate_center": {_x000D_ "country": "US",_x000D_ "prefix": "1",_x000D_ "tollfree": false_x000D_ },_x000D_ "business_number": null,_x000D_ "business_label": null,_x000D_ "receiving_number_id": null,_x000D_ "receiving_number_sid": null,_x000D_ "billed_amount": 0,_x000D_ "billed_at": "0001-01-01T00:00:00",_x000D_ "excluded": false,_x000D_ "redacted": false,_x000D_ "tracking_number_format": "(435) 254-1043",_x000D_ "business_number_format": null,_x000D_ "alternative_number": "2015552012",_x000D_ "tracking_number_bare": "4352541043",_x000D_ "caller_number_format": "(201) 555-2012",_x000D_ "caller_number_complete": "\u002B12015552012",_x000D_ "caller_number_bare": "2015552012",_x000D_ "caller_number": "\u002B12015552012",_x000D_ "caller_number_split": [_x000D_ "1",_x000D_ "201",_x000D_ "555",_x000D_ "2012"_x000D_ ],_x000D_ "contact_number": "\u002B12015552012",_x000D_ "visitor": false,_x000D_ "call_path": [_x000D_ {_x000D_ "route_name": "_OnHangup_CallSync",_x000D_ "route_id": "640990",_x000D_ "route_type": "RoutingRule",_x000D_ "started_at": "2026-02-19T20:47:30Z"_x000D_ }_x000D_ ],_x000D_ "left_talk_time": 0,_x000D_ "right_talk_time": 0,_x000D_ "transfers": [],_x000D_ "call_status": "completed",_x000D_ "status": "completed",_x000D_ "spotted": [],_x000D_ "salesforce": {},_x000D_ "audio": null,_x000D_ "is_s3_link": false,_x000D_ "callbacks": [],_x000D_ "emails": [],_x000D_ "day": "Thursday",_x000D_ "month": "February",_x000D_ "hour": "08PM",_x000D_ "paid": {_x000D_ "source": null,_x000D_ "medium": null_x000D_ },_x000D_ "ga": {_x000D_ "cid": "441826.4037107502",_x000D_ "ga4": []_x000D_ },_x000D_ "tag_list": [],_x000D_ "latitude": 0,_x000D_ "longitude": 0,_x000D_ "extended_lookup_on": true,_x000D_ "form": {_x000D_ "number_to_call": "log-call-no-answer-797e6992881f801e",_x000D_ "customer_number_to_dial": "\u002B12015552012",_x000D_ "name": "Shirley Desimone",_x000D_ "email": "shirleydesimone.mkt@gmail.com",_x000D_ "trackback_id": "trackback-441826.1771559248.976668",_x000D_ "form_id": 213071,_x000D_ "form_name": "Contact Us",_x000D_ "custom": [_x000D_ {_x000D_ "label": "Referral Source",_x000D_ "value": "",_x000D_ "id": "referral_source"_x000D_ },_x000D_ {_x000D_ "label": "UTM Source",_x000D_ "value": "",_x000D_ "id": "utm_source"_x000D_ },_x000D_ {_x000D_ "label": "UTM Medium",_x000D_ "value": "",_x000D_ "id": "utm_medium"_x000D_ },_x000D_ {_x000D_ "label": "UTM Campaign",_x000D_ "value": "",_x000D_ "id": "utm_campaign"_x000D_ },_x000D_ {_x000D_ "label": "UTM Term",_x000D_ "value": "",_x000D_ "id": "utm_term"_x000D_ },_x000D_ {_x000D_ "label": "UTM Content",_x000D_ "value": "",_x000D_ "id": "utm_content"_x000D_ }_x000D_ ]_x000D_ },_x000D_ "legs": [],_x000D_ "touchpoints": null,_x000D_ "last_touch": null,_x000D_ "geo": {_x000D_ "lon": 0,_x000D_ "lat": 0_x000D_ },_x000D_ "timestamp": "0001-01-01T00:00:00"_x000D_ } | E3: 0 | F3: 1 | Q3: 0 | R3: 4037107502 | S3: 2 | T3: 2026
A4: 2019540776 | B4: 46077.745 | C4: {_x000D_ "id": 4045325210,_x000D_ "sid": "log-call-no-answer-d52a60c5df94ade0",_x000D_ "account_id": 441826,_x000D_ "name": "NOOR JANJUA",_x000D_ "cnam": "NOOR JANJUA",_x000D_ "search": "",_x000D_ "referrer": "",_x000D_ "visitor_sid": "",_x000D_ "location": "",_x000D_ "source": "Sandbox",_x000D_ "source_id": 1814974,_x000D_ "source_sid": "TSOF6FC2D2594D22C5288F2F91D669A9D5B9BE7FEE3C6EF44F4A9EA1A63913ECD83",_x000D_ "tgid": 5681974,_x000D_ "likelihood": null,_x000D_ "duration": 0,_x000D_ "direction": "form",_x000D_ "talk_time": 0,_x000D_ "ring_time": 0,_x000D_ "hold_time": 0,_x000D_ "wait_time": 0,_x000D_ "parent_id": null,_x000D_ "email": "NOORJANJUA@FEDERONSOLUTIONS.COM",_x000D_ "street": null,_x000D_ "city": "Caldwell",_x000D_ "state": "NJ",_x000D_ "country": null,_x000D_ "postal_code": "07004",_x000D_ "called_at": "2026-02-24 11:53 AM -06:00",_x000D_ "unix_time": 1771959218,_x000D_ "tracking_number_id": 3476065,_x000D_ "tracking_number_sid": "TPNC3C4B23C348AEC2EE54EFD301979CD2EFFBA32881B159867D3F4ED59E6F0B56367EFF2993536685F",_x000D_ "tracking_number": "\u002B14352541043",_x000D_ "tracking_label": "Testing Number",_x000D_ "dial_status": "no-answer",_x000D_ "is_new_caller": true,_x000D_ "indexed_at": 1.7719598E+09,_x000D_ "agent_insights": false,_x000D_ "duration_period": {_x000D_ "gte": 1771959218000,_x000D_ "lte": 1771959218000_x000D_ },_x000D_ "inbound_rate_center": {_x000D_ "country": "US",_x000D_ "prefix": "1",_x000D_ "tollfree": false_x000D_ },_x000D_ "business_number": null,_x000D_ "business_label": null,_x000D_ "receiving_number_id": null,_x000D_ "receiving_number_sid": null,_x000D_ "billed_amount": 0,_x000D_ "billed_at": "0001-01-01T00:00:00",_x000D_ "excluded": false,_x000D_ "redacted": false,_x000D_ "tracking_number_format": "(435) 254-1043",_x000D_ "business_number_format": null,_x000D_ "alternative_number": "2019540776",_x000D_ "tracking_number_bare": "4352541043",_x000D_ "caller_number_format": "(201) 954-0776",_x000D_ "caller_number_complete": "\u002B12019540776",_x000D_ "caller_number_bare": "2019540776",_x000D_ "caller_number": "\u002B12019540776",_x000D_ "caller_number_split": [_x000D_ "1",_x000D_ "201",_x000D_ "954",_x000D_ "0776"_x000D_ ],_x000D_ "contact_number": "\u002B12019540776",_x000D_ "visitor": false,_x000D_ "call_path": [_x000D_ {_x000D_ "route_name": "_OnHangup_CallSync",_x000D_ "route_id": "640990",_x000D_ "route_type": "RoutingRule",_x000D_ "started_at": "2026-02-24T11:53:39Z"_x000D_ }_x000D_ ],_x000D_ "left_talk_time": 0,_x000D_ "right_talk_time": 0,_x000D_ "transfers": [],_x000D_ "call_status": "completed",_x000D_ "status": "completed",_x000D_ "spotted": [],_x000D_ "salesforce": {},_x000D_ "audio": null,_x000D_ "is_s3_link": false,_x000D_ "callbacks": [],_x000D_ "emails": [],_x000D_ "day": "Tuesday",_x000D_ "month": "February",_x000D_ "hour": "11AM",_x000D_ "paid": {_x000D_ "source": null,_x000D_ "medium": null_x000D_ },_x000D_ "ga": {_x000D_ "cid": "441826.4045325210",_x000D_ "ga4": []_x000D_ },_x000D_ "tag_list": [],_x000D_ "latitude": 40.8421,_x000D_ "longitude": -74.2742,_x000D_ "extended_lookup_on": true,_x000D_ "form": {_x000D_ "number_to_call": "log-call-no-answer-846aa5f9c9480080",_x000D_ "customer_number_to_dial": "\u002B12019540776",_x000D_ "name": "NOOR JANJUA",_x000D_ "email": "NOORJANJUA@FEDERONSOLUTIONS.COM",_x000D_ "trackback_id": "trackback-441826.1771959218.238851",_x000D_ "form_id": 213071,_x000D_ "form_name": "Contact Us",_x000D_ "custom": [_x000D_ {_x000D_ "label": "Referral Source",_x000D_ "value": "",_x000D_ "id": "referral_source"_x000D_ },_x000D_ {_x000D_ "label": "UTM Source",_x000D_ "value": "",_x000D_ "id": "utm_source"_x000D_ },_x000D_ {_x000D_ "label": "UTM Medium",_x000D_ "value": "",_x000D_ "id": "utm_medium"_x000D_ },_x000D_ {_x000D_ "label": "UTM Campaign",_x000D_ "value": "",_x000D_ "id": "utm_campaign"_x000D_ },_x000D_ {_x000D_ "label": "UTM Term",_x000D_ "value": "",_x000D_ "id": "utm_term"_x000D_ },_x000D_ {_x000D_ "label": "UTM Content",_x000D_ "value": "",_x000D_ "id": "utm_content"_x000D_ }_x000D_ ]_x000D_ },_x000D_ "legs": [],_x000D_ "touchpoints": null,_x000D_ "last_touch": null,_x000D_ "geo": {_x000D_ "lon": -74.2742,_x000D_ "lat": 40.8421_x000D_ },_x000D_ "timestamp": "0001-01-01T00:00:00"_x000D_ } | E4: 0 | F4: 1 | Q4: 0 | R4: 4045325210 | S4: 2 | T4: 2026
A5: 2019540776 | B5: 46077.745 | C5: {_x000D_ "id": 4045325453,_x000D_ "sid": "log-call-no-answer-6d53d95e96da5b3e",_x000D_ "account_id": 441826,_x000D_ "name": "NOOR JANJUA",_x000D_ "cnam": "NOOR JANJUA",_x000D_ "search": "",_x000D_ "referrer": "",_x000D_ "visitor_sid": "",_x000D_ "location": "",_x000D_ "source": "Sandbox",_x000D_ "source_id": 1814974,_x000D_ "source_sid": "TSOF6FC2D2594D22C5288F2F91D669A9D5B9BE7FEE3C6EF44F4A9EA1A63913ECD83",_x000D_ "tgid": 5681974,_x000D_ "likelihood": null,_x000D_ "duration": 0,_x000D_ "direction": "form",_x000D_ "talk_time": 0,_x000D_ "ring_time": 0,_x000D_ "hold_time": 0,_x000D_ "wait_time": 0,_x000D_ "parent_id": null,_x000D_ "email": "NOORJANJUA@FEDERONSOLUTIONS.COM",_x000D_ "street": null,_x000D_ "city": "Caldwell",_x000D_ "state": "NJ",_x000D_ "country": null,_x000D_ "postal_code": "07004",_x000D_ "called_at": "2026-02-24 11:53 AM -06:00",_x000D_ "unix_time": 1771959221,_x000D_ "tracking_number_id": 3476065,_x000D_ "tracking_number_sid": "TPNC3C4B23C348AEC2EE54EFD301979CD2EFFBA32881B159867D3F4ED59E6F0B56367EFF2993536685F",_x000D_ "tracking_number": "\u002B14352541043",_x000D_ "tracking_label": "Testing Number",_x000D_ "dial_status": "no-answer",_x000D_ "is_new_caller": false,_x000D_ "indexed_at": 1.7719598E+09,_x000D_ "agent_insights": false,_x000D_ "duration_period": {_x000D_ "gte": 1771959221000,_x000D_ "lte": 1771959221000_x000D_ },_x000D_ "inbound_rate_center": {_x000D_ "country": "US",_x000D_ "prefix": "1",_x000D_ "tollfree": false_x000D_ },_x000D_ "business_number": null,_x000D_ "business_label": null,_x000D_ "receiving_number_id": null,_x000D_ "receiving_number_sid": null,_x000D_ "billed_amount": 0,_x000D_ "billed_at": "0001-01-01T00:00:00",_x000D_ "excluded": false,_x000D_ "redacted": false,_x000D_ "tracking_number_format": "(435) 254-1043",_x000D_ "business_number_format": null,_x000D_ "alternative_number": "2019540776",_x000D_ "tracking_number_bare": "4352541043",_x000D_ "caller_number_format": "(201) 954-0776",_x000D_ "caller_number_complete": "\u002B12019540776",_x000D_ "caller_number_bare": "2019540776",_x000D_ "caller_number": "\u002B12019540776",_x000D_ "caller_number_split": [_x000D_ "1",_x000D_ "201",_x000D_ "954",_x000D_ "0776"_x000D_ ],_x000D_ "contact_number": "\u002B12019540776",_x000D_ "visitor": false,_x000D_ "call_path": [_x000D_ {_x000D_ "route_name": "_OnHangup_CallSync",_x000D_ "route_id": "640990",_x000D_ "route_type": "RoutingRule",_x000D_ "started_at": "2026-02-24T11:53:42Z"_x000D_ }_x000D_ ],_x000D_ "left_talk_time": 0,_x000D_ "right_talk_time": 0,_x000D_ "transfers": [],_x000D_ "call_status": "completed",_x000D_ "status": "completed",_x000D_ "spotted": [],_x000D_ "salesforce": {},_x000D_ "audio": null,_x000D_ "is_s3_link": false,_x000D_ "callbacks": [],_x000D_ "emails": [],_x000D_ "day": "Tuesday",_x000D_ "month": "February",_x000D_ "hour": "11AM",_x000D_ "paid": {_x000D_ "source": null,_x000D_ "medium": null_x000D_ },_x000D_ "ga": {_x000D_ "cid": "441826.4045325453",_x000D_ "ga4": []_x000D_ },_x000D_ "tag_list": [],_x000D_ "latitude": 40.8421,_x000D_ "longitude": -74.2742,_x000D_ "extended_lookup_on": true,_x000D_ "form": {_x000D_ "number_to_call": "log-call-no-answer-942947867fe93594",_x000D_ "customer_number_to_dial": "\u002B12019540776",_x000D_ "name": "NOOR JANJUA",_x000D_ "email": "NOORJANJUA@FEDERONSOLUTIONS.COM",_x000D_ "trackback_id": "trackback-441826.1771959221.2178426",_x000D_ "form_id": 213071,_x000D_ "form_name": "Contact Us",_x000D_ "custom": [_x000D_ {_x000D_ "label": "Referral Source",_x000D_ "value": "",_x000D_ "id": "referral_source"_x000D_ },_x000D_ {_x000D_ "label": "UTM Source",_x000D_ "value": "",_x000D_ "id": "utm_source"_x000D_ },_x000D_ {_x000D_ "label": "UTM Medium",_x000D_ "value": "",_x000D_ "id": "utm_medium"_x000D_ },_x000D_ {_x000D_ "label": "UTM Campaign",_x000D_ "value": "",_x000D_ "id": "utm_campaign"_x000D_ },_x000D_ {_x000D_ "label": "UTM Term",_x000D_ "value": "",_x000D_ "id": "utm_term"_x000D_ },_x000D_ {_x000D_ "label": "UTM Content",_x000D_ "value": "",_x000D_ "id": "utm_content"_x000D_ }_x000D_ ]_x000D_ },_x000D_ "legs": [],_x000D_ "touchpoints": null,_x000D_ "last_touch": null,_x000D_ "geo": {_x000D_ "lon": -74.2742,_x000D_ "lat": 40.8421_x000D_ },_x000D_ "timestamp": "0001-01-01T00:00:00"_x000D_ } | E5: 0 | F5: 1 | Q5: 0 | R5: 4045325453 | S5: 2 | T5: 2026
A6: 2032475134 | B6: 46078.858 | C6: {_x000D_ "id": 4048720598,_x000D_ "sid": "log-call-no-answer-b407f04eca782aab",_x000D_ "account_id": 441826,_x000D_ "name": "Nancye Fritz",_x000D_ "cnam": "Nancye Fritz",_x000D_ "search": "",_x000D_ "referrer": "",_x000D_ "visitor_sid": "",_x000D_ "location": "",_x000D_ "source": "Sandbox",_x000D_ "source_id": 1814974,_x000D_ "source_sid": "TSOF6FC2D2594D22C5288F2F91D669A9D5B9BE7FEE3C6EF44F4A9EA1A63913ECD83",_x000D_ "tgid": 5681974,_x000D_ "likelihood": null,_x000D_ "duration": 0,_x000D_ "direction": "form",_x000D_ "talk_time": 0,_x000D_ "ring_time": 0,_x000D_ "hold_time": 0,_x000D_ "wait_time": 0,_x000D_ "parent_id": null,_x000D_ "email": "nancyefritz1980@gmail.com",_x000D_ "street": null,_x000D_ "city": "Norwalk",_x000D_ "state": "CT",_x000D_ "country": null,_x000D_ "postal_code": "06850",_x000D_ "called_at": "2026-02-25 02:36 PM -06:00",_x000D_ "unix_time": 1772055365,_x000D_ "tracking_number_id": 3476065,_x000D_ "tracking_number_sid": "TPNC3C4B23C348AEC2EE54EFD301979CD2EFFBA32881B159867D3F4ED59E6F0B56367EFF2993536685F",_x000D_ "tracking_number": "\u002B14352541043",_x000D_ "tracking_label": "Testing Number",_x000D_ "dial_status": "no-answer",_x000D_ "is_new_caller": true,_x000D_ "indexed_at": 1.7720559E+09,_x000D_ "agent_insights": false,_x000D_ "duration_period": {_x000D_ "gte": 1772055365000,_x000D_ "lte": 1772055365000_x000D_ },_x000D_ "inbound_rate_center": {_x000D_ "country": "US",_x000D_ "prefix": "1",_x000D_ "tollfree": false_x000D_ },_x000D_ "business_number": null,_x000D_ "business_label": null,_x000D_ "receiving_number_id": null,_x000D_ "receiving_number_sid": null,_x000D_ "billed_amount": 0,_x000D_ "billed_at": "0001-01-01T00:00:00",_x000D_ "excluded": false,_x000D_ "redacted": false,_x000D_ "tracking_number_format": "(435) 254-1043",_x000D_ "business_number_format": null,_x000D_ "alternative_number": "2032475134",_x000D_ "tracking_number_bare": "4352541043",_x000D_ "caller_number_format": "(203) 247-5134",_x000D_ "caller_number_complete": "\u002B12032475134",_x000D_ "caller_number_bare": "2032475134",_x000D_ "caller_number": "\u002B12032475134",_x000D_ "caller_number_split": [_x000D_ "1",_x000D_ "203",_x000D_ "247",_x000D_ "5134"_x000D_ ],_x000D_ "contact_number": "\u002B12032475134",_x000D_ "visitor": false,_x000D_ "call_path": [_x000D_ {_x000D_ "route_name": "_OnHangup_CallSync",_x000D_ "route_id": "640990",_x000D_ "route_type": "RoutingRule",_x000D_ "started_at": "2026-02-25T14:36:06Z"_x000D_ }_x000D_ ],_x000D_ "left_talk_time": 0,_x000D_ "right_talk_time": 0,_x000D_ "transfers": [],_x000D_ "call_status": "completed",_x000D_ "status": "completed",_x000D_ "spotted": [],_x000D_ "salesforce": {},_x000D_ "audio": null,_x000D_ "is_s3_link": false,_x000D_ "callbacks": [],_x000D_ "emails": [],_x000D_ "day": "Wednesday",_x000D_ "month": "February",_x000D_ "hour": "02PM",_x000D_ "paid": {_x000D_ "source": null,_x000D_ "medium": null_x000D_ },_x000D_ "ga": {_x000D_ "cid": "441826.4048720598",_x000D_ "ga4": []_x000D_ },_x000D_ "tag_list": [],_x000D_ "latitude": 41.1144,_x000D_ "longitude": -73.4054,_x000D_ "extended_lookup_on": true,_x000D_ "form": {_x000D_ "number_to_call": "log-call-no-answer-9adb8cfc697ea8dc",_x000D_ "customer_number_to_dial": "\u002B12032475134",_x000D_ "name": "Nancye Fritz",_x000D_ "email": "nancyefritz1980@gmail.com",_x000D_ "trackback_id": "trackback-441826.1772055365.2770667",_x000D_ "form_id": 213071,_x000D_ "form_name": "Contact Us",_x000D_ "custom": [_x000D_ {_x000D_ "label": "Referral Source",_x000D_ "value": "",_x000D_ "id": "referral_source"_x000D_ },_x000D_ {_x000D_ "label": "UTM Source",_x000D_ "value": "",_x000D_ "id": "utm_source"_x000D_ },_x000D_ {_x000D_ "label": "UTM Medium",_x000D_ "value": "",_x000D_ "id": "utm_medium"_x000D_ },_x000D_ {_x000D_ "label": "UTM Campaign",_x000D_ "value": "",_x000D_ "id": "utm_campaign"_x000D_ },_x000D_ {_x000D_ "label": "UTM Term",_x000D_ "value": "",_x000D_ "id": "utm_term"_x000D_ },_x000D_ {_x000D_ "label": "UTM Content",_x000D_ "value": "",_x000D_ "id": "utm_content"_x000D_ }_x000D_ ]_x000D_ },_x000D_ "legs": [],_x000D_ "touchpoints": null,_x000D_ "last_touch": null,_x000D_ "geo": {_x000D_ "lon": -73.4054,_x000D_ "lat": 41.1144_x000D_ },_x000D_ "timestamp": "0001-01-01T00:00:00"_x000D_ } | E6: 1 | F6: 1 | G6: 1524101 | H6: 1 | I6: 46078.91 | K6: 1772200 | L6: 1 | M6: 990 | N6: 46078.91 | P6: Fox Home Protection Plan | Q6: 1 | R6: 4048720598 | S6: 2 | T6: 2026
A7: 2032579728 | B7: 46073.606 | C7: {_x000D_ "id": 4037656223,_x000D_ "sid": "log-call-no-answer-584bcd0113e12e57",_x000D_ "account_id": 441826,_x000D_ "name": "KING ROGERS",_x000D_ "cnam": "KING ROGERS",_x000D_ "search": "",_x000D_ "referrer": "",_x000D_ "visitor_sid": "",_x000D_ "location": "",_x000D_ "source": "Sandbox",_x000D_ "source_id": 1814974,_x000D_ "source_sid": "TSOF6FC2D2594D22C5288F2F91D669A9D5B9BE7FEE3C6EF44F4A9EA1A63913ECD83",_x000D_ "tgid": 5681974,_x000D_ "likelihood": null,_x000D_ "duration": 0,_x000D_ "direction": "form",_x000D_ "talk_time": 0,_x000D_ "ring_time": 0,_x000D_ "hold_time": 0,_x000D_ "wait_time": 0,_x000D_ "parent_id": null,_x000D_ "email": "kingerogers@gmail.com",_x000D_ "street": null,_x000D_ "city": null,_x000D_ "state": null,_x000D_ "country": null,_x000D_ "postal_code": "06601",_x000D_ "called_at": "2026-02-20 08:33 AM -06:00",_x000D_ "unix_time": 1771601584,_x000D_ "tracking_number_id": 3476065,_x000D_ "tracking_number_sid": "TPNC3C4B23C348AEC2EE54EFD301979CD2EFFBA32881B159867D3F4ED59E6F0B56367EFF2993536685F",_x000D_ "tracking_number": "\u002B14352541043",_x000D_ "tracking_label": "Testing Number",_x000D_ "dial_status": "no-answer",_x000D_ "is_new_caller": true,_x000D_ "indexed_at": 1.7716022E+09,_x000D_ "agent_insights": false,_x000D_ "duration_period": {_x000D_ "gte": 1771601584000,_x000D_ "lte": 1771601584000_x000D_ },_x000D_ "inbound_rate_center": {_x000D_ "country": "US",_x000D_ "prefix": "1",_x000D_ "tollfree": false_x000D_ },_x000D_ "business_number": null,_x000D_ "business_label": null,_x000D_ "receiving_number_id": null,_x000D_ "receiving_number_sid": null,_x000D_ "billed_amount": 0,_x000D_ "billed_at": "0001-01-01T00:00:00",_x000D_ "excluded": false,_x000D_ "redacted": false,_x000D_ "tracking_number_format": "(435) 254-1043",_x000D_ "business_number_format": null,_x000D_ "alternative_number": "2032579728",_x000D_ "tracking_number_bare": "4352541043",_x000D_ "caller_number_format": "(203) 257-9728",_x000D_ "caller_number_complete": "\u002B12032579728",_x000D_ "caller_number_bare": "2032579728",_x000D_ "caller_number": "\u002B12032579728",_x000D_ "caller_number_split": [_x000D_ "1",_x000D_ "203",_x000D_ "257",_x000D_ "9728"_x000D_ ],_x000D_ "contact_number": "\u002B12032579728",_x000D_ "visitor": false,_x000D_ "call_path": [_x000D_ {_x000D_ "route_name": "_OnHangup_CallSync",_x000D_ "route_id": "640990",_x000D_ "route_type": "RoutingRule",_x000D_ "started_at": "2026-02-20T08:33:06Z"_x000D_ }_x000D_ ],_x000D_ "left_talk_time": 0,_x000D_ "right_talk_time": 0,_x000D_ "transfers": [],_x000D_ "call_status": "completed",_x000D_ "status": "completed",_x000D_ "spotted": [],_x000D_ "salesforce": {},_x000D_ "audio": null,_x000D_ "is_s3_link": false,_x000D_ "callbacks": [],_x000D_ "emails": [],_x000D_ "day": "Friday",_x000D_ "month": "February",_x000D_ "hour": "08AM",_x000D_ "paid": {_x000D_ "source": null,_x000D_ "medium": null_x000D_ },_x000D_ "ga": {_x000D_ "cid": "441826.4037656223",_x000D_ "ga4": []_x000D_ },_x000D_ "tag_list": [],_x000D_ "latitude": 41.1854,_x000D_ "longitude": -73.1962,_x000D_ "extended_lookup_on": true,_x000D_ "form": {_x000D_ "number_to_call": "log-call-no-answer-9d5004bb25a3fb04",_x000D_ "customer_number_to_dial": "\u002B12032579728",_x000D_ "name": "KING ROGERS",_x000D_ "email": "kingerogers@gmail.com",_x000D_ "trackback_id": "trackback-441826.1771601584.903589",_x000D_ "form_id": 213071,_x000D_ "form_name": "Contact Us",_x000D_ "custom": [_x000D_ {_x000D_ "label": "Referral Source",_x000D_ "value": "",_x000D_ "id": "referral_source"_x000D_ },_x000D_ {_x000D_ "label": "UTM Source",_x000D_ "value": "",_x000D_ "id": "utm_source"_x000D_ },_x000D_ {_x000D_ "label": "UTM Medium",_x000D_ "value": "",_x000D_ "id": "utm_medium"_x000D_ },_x000D_ {_x000D_ "label": "UTM Campaign",_x000D_ "value": "",_x000D_ "id": "utm_campaign"_x000D_ },_x000D_ {_x000D_ "label": "UTM Term",_x000D_ "value": "",_x000D_ "id": "utm_term"_x000D_ },_x000D_ {_x000D_ "label": "UTM Content",_x000D_ "value": "",_x000D_ "id": "utm_content"_x000D_ }_x000D_ ]_x000D_ },_x000D_ "legs": [],_x000D_ "touchpoints": null,_x000D_ "last_touch": null,_x000D_ "geo": {_x000D_ "lon": -73.1962,_x000D_ "lat": 41.1854_x000D_ },_x000D_ "timestamp": "0001-01-01T00:00:00"_x000D_ } | E7: 1 | F7: 1 | G7: 1523620 | H7: 1 | I7: 46073.66 | K7: 1770124 | L7: 1 | M7: 922 | N7: 46073.815 | P7: Fox Home Protection Plan | Q7: 1 | R7: 4037656223 | S7: 2 | T7: 2026
A8: 2034170861 | B8: 46073.471 | C8: {_x000D_ "id": 4037301011,_x000D_ "sid": "log-call-no-answer-53677125109bc665",_x000D_ "account_id": 441826,_x000D_ "name": "Shellby Nelson",_x000D_ "cnam": "Shellby Nelson",_x000D_ "search": "",_x000D_ "referrer": "",_x000D_ "visitor_sid": "",_x000D_ "location": "",_x000D_ "source": "Sandbox",_x000D_ "source_id": 1814974,_x000D_ "source_sid": "TSOF6FC2D2594D22C5288F2F91D669A9D5B9BE7FEE3C6EF44F4A9EA1A63913ECD83",_x000D_ "tgid": 5681974,_x000D_ "likelihood": null,_x000D_ "duration": 0,_x000D_ "direction": "form",_x000D_ "talk_time": 0,_x000D_ "ring_time": 0,_x000D_ "hold_time": 0,_x000D_ "wait_time": 0,_x000D_ "parent_id": null,_x000D_ "email": "shellnele@yahoo.com",_x000D_ "street": null,_x000D_ "city": null,_x000D_ "state": null,_x000D_ "country": null,_x000D_ "postal_code": "06801",_x000D_ "called_at": "2026-02-20 05:18 AM -06:00",_x000D_ "unix_time": 1771589923,_x000D_ "tracking_number_id": 3476065,_x000D_ "tracking_number_sid": "TPNC3C4B23C348AEC2EE54EFD301979CD2EFFBA32881B159867D3F4ED59E6F0B56367EFF2993536685F",_x000D_ "tracking_number": "\u002B14352541043",_x000D_ "tracking_label": "Testing Number",_x000D_ "dial_status": "no-answer",_x000D_ "is_new_caller": true,_x000D_ "indexed_at": 1.7715905E+09,_x000D_ "agent_insights": false,_x000D_ "duration_period": {_x000D_ "gte": 1771589923000,_x000D_ "lte": 1771589923000_x000D_ },_x000D_ "inbound_rate_center": {_x000D_ "country": "US",_x000D_ "prefix": "1",_x000D_ "tollfree": false_x000D_ },_x000D_ "business_number": null,_x000D_ "business_label": null,_x000D_ "receiving_number_id": null,_x000D_ "receiving_number_sid": null,_x000D_ "billed_amount": 0,_x000D_ "billed_at": "0001-01-01T00:00:00",_x000D_ "excluded": false,_x000D_ "redacted": false,_x000D_ "tracking_number_format": "(435) 254-1043",_x000D_ "business_number_format": null,_x000D_ "alternative_number": "2034170861",_x000D_ "tracking_number_bare": "4352541043",_x000D_ "caller_number_format": "(203) 417-0861",_x000D_ "caller_number_complete": "\u002B12034170861",_x000D_ "caller_number_bare": "2034170861",_x000D_ "caller_number": "\u002B12034170861",_x000D_ "caller_number_split": [_x000D_ "1",_x000D_ "203",_x000D_ "417",_x000D_ "0861"_x000D_ ],_x000D_ "contact_number": "\u002B12034170861",_x000D_ "visitor": false,_x000D_ "call_path": [_x000D_ {_x000D_ "route_name": "_OnHangup_CallSync",_x000D_ "route_id": "640990",_x000D_ "route_type": "RoutingRule",_x000D_ "started_at": "2026-02-20T05:18:45Z"_x000D_ }_x000D_ ],_x000D_ "left_talk_time": 0,_x000D_ "right_talk_time": 0,_x000D_ "transfers": [],_x000D_ "call_status": "completed",_x000D_ "status": "completed",_x000D_ "spotted": [],_x000D_ "salesforce": {},_x000D_ "audio": null,_x000D_ "is_s3_link": false,_x000D_ "callbacks": [],_x000D_ "emails": [],_x000D_ "day": "Friday",_x000D_ "month": "February",_x000D_ "hour": "05AM",_x000D_ "paid": {_x000D_ "source": null,_x000D_ "medium": null_x000D_ },_x000D_ "ga": {_x000D_ "cid": "441826.4037301011",_x000D_ "ga4": []_x000D_ },_x000D_ "tag_list": [],_x000D_ "latitude": 41.3953,_x000D_ "longitude": -73.4549,_x000D_ "extended_lookup_on": true,_x000D_ "form": {_x000D_ "number_to_call": "log-call-no-answer-61fccda2e3f44d9b",_x000D_ "customer_number_to_dial": "\u002B12034170861",_x000D_ "name": "Shellby Nelson",_x000D_ "email": "shellnele@yahoo.com",_x000D_ "trackback_id": "trackback-441826.1771589923.9501972",_x000D_ "form_id": 213071,_x000D_ "form_name": "Contact Us",_x000D_ "custom": [_x000D_ {_x000D_ "label": "Referral Source",_x000D_ "value": "",_x000D_ "id": "referral_source"_x000D_ },_x000D_ {_x000D_ "label": "UTM Source",_x000D_ "value": "",_x000D_ "id": "utm_source"_x000D_ },_x000D_ {_x000D_ "label": "UTM Medium",_x000D_ "value": "",_x000D_ "id": "utm_medium"_x000D_ },_x000D_ {_x000D_ "label": "UTM Campaign",_x000D_ "value": "",_x000D_ "id": "utm_campaign"_x000D_ },_x000D_ {_x000D_ "label": "UTM Term",_x000D_ "value": "",_x000D_ "id": "utm_term"_x000D_ },_x000D_ {_x000D_ "label": "UTM Content",_x000D_ "value": "",_x000D_ "id": "utm_content"_x000D_ }_x000D_ ]_x000D_ },_x000D_ "legs": [],_x000D_ "touchpoints": null,_x000D_ "last_touch": null,_x000D_ "geo": {_x000D_ "lon": -73.4549,_x000D_ "lat": 41.3953_x000D_ },_x000D_ "timestamp": "0001-01-01T00:00:00"_x000D_ } | E8: 0 | F8: 1 | Q8: 0 | R8: 4037301011 | S8: 2 | T8: 2026
A9: 2037672791 | B9: 46072.642 | C9: {_x000D_ "id": 4035180260,_x000D_ "sid": "log-call-no-answer-eab917ad5defb933",_x000D_ "account_id": 441826,_x000D_ "name": "Stephanie Spinetti",_x000D_ "cnam": "Stephanie Spinetti",_x000D_ "search": "",_x000D_ "referrer": "",_x000D_ "visitor_sid": "",_x000D_ "location": "",_x000D_ "source": "Sandbox",_x000D_ "source_id": 1814974,_x000D_ "source_sid": "TSOF6FC2D2594D22C5288F2F91D669A9D5B9BE7FEE3C6EF44F4A9EA1A63913ECD83",_x000D_ "tgid": 5681974,_x000D_ "likelihood": null,_x000D_ "duration": 0,_x000D_ "direction": "form",_x000D_ "talk_time": 0,_x000D_ "ring_time": 0,_x000D_ "hold_time": 0,_x000D_ "wait_time": 0,_x000D_ "parent_id": null,_x000D_ "email": "stephanie.spinetti@gmail.com",_x000D_ "street": null,_x000D_ "city": null,_x000D_ "state": null,_x000D_ "country": null,_x000D_ "postal_code": "06601",_x000D_ "called_at": "2026-02-19 09:24 AM -06:00",_x000D_ "unix_time": 1771518247,_x000D_ "tracking_number_id": 3476065,_x000D_ "tracking_number_sid": "TPNC3C4B23C348AEC2EE54EFD301979CD2EFFBA32881B159867D3F4ED59E6F0B56367EFF2993536685F",_x000D_ "tracking_number": "\u002B14352541043",_x000D_ "tracking_label": "Testing Number",_x000D_ "dial_status": "no-answer",_x000D_ "is_new_caller": true,_x000D_ "indexed_at": 1.7715188E+09,_x000D_ "agent_insights": false,_x000D_ "duration_period": {_x000D_ "gte": 1771518247000,_x000D_ "lte": 1771518247000_x000D_ },_x000D_ "inbound_rate_center": {_x000D_ "country": "US",_x000D_ "prefix": "1",_x000D_ "tollfree": false_x000D_ },_x000D_ "business_number": null,_x000D_ "business_label": null,_x000D_ "receiving_number_id": null,_x000D_ "receiving_number_sid": null,_x000D_ "billed_amount": 0,_x000D_ "billed_at": "0001-01-01T00:00:00",_x000D_ "excluded": false,_x000D_ "redacted": false,_x000D_ "tracking_number_format": "(435) 254-1043",_x000D_ "business_number_format": null,_x000D_ "alternative_number": "2037672791",_x000D_ "tracking_number_bare": "4352541043",_x000D_ "caller_number_format": "(203) 767-2791",_x000D_ "caller_number_complete": "\u002B12037672791",_x000D_ "caller_number_bare": "2037672791",_x000D_ "caller_number": "\u002B12037672791",_x000D_ "caller_number_split": [_x000D_ "1",_x000D_ "203",_x000D_ "767",_x000D_ "2791"_x000D_ ],_x000D_ "contact_number": "\u002B12037672791",_x000D_ "visitor": false,_x000D_ "call_path": [_x000D_ {_x000D_ "route_name": "_OnHangup_CallSync",_x000D_ "route_id": "640990",_x000D_ "route_type": "RoutingRule",_x000D_ "started_at": "2026-02-19T09:24:08Z"_x000D_ }_x000D_ ],_x000D_ "left_talk_time": 0,_x000D_ "right_talk_time": 0,_x000D_ "transfers": [],_x000D_ "call_status": "completed",_x000D_ "status": "completed",_x000D_ "spotted": [],_x000D_ "salesforce": {},_x000D_ "audio": null,_x000D_ "is_s3_link": false,_x000D_ "callbacks": [],_x000D_ "emails": [],_x000D_ "day": "Thursday",_x000D_ "month": "February",_x000D_ "hour": "09AM",_x000D_ "paid": {_x000D_ "source": null,_x000D_ "medium": null_x000D_ },_x000D_ "ga": {_x000D_ "cid": "441826.4035180260",_x000D_ "ga4": []_x000D_ },_x000D_ "tag_list": [],_x000D_ "latitude": 41.1854,_x000D_ "longitude": -73.1962,_x000D_ "extended_lookup_on": true,_x000D_ "form": {_x000D_ "number_to_call": "log-call-no-answer-d517d295cda62feb",_x000D_ "customer_number_to_dial": "\u002B12037672791",_x000D_ "name": "Stephanie Spinetti",_x000D_ "email": "stephanie.spinetti@gmail.com",_x000D_ "trackback_id": "trackback-441826.1771518247.7941082",_x000D_ "form_id": 213071,_x000D_ "form_name": "Contact Us",_x000D_ "custom": [_x000D_ {_x000D_ "label": "Referral Source",_x000D_ "value": "",_x000D_ "id": "referral_source"_x000D_ },_x000D_ {_x000D_ "label": "UTM Source",_x000D_ "value": "",_x000D_ "id": "utm_source"_x000D_ },_x000D_ {_x000D_ "label": "UTM Medium",_x000D_ "value": "",_x000D_ "id": "utm_medium"_x000D_ },_x000D_ {_x000D_ "label": "UTM Campaign",_x000D_ "value": "",_x000D_ "id": "utm_campaign"_x000D_ },_x000D_ {_x000D_ "label": "UTM Term",_x000D_ "value": "",_x000D_ "id": "utm_term"_x000D_ },_x000D_ {_x000D_ "label": "UTM Content",_x000D_ "value": "",_x000D_ "id": "utm_content"_x000D_ }_x000D_ ]_x000D_ },_x000D_ "legs": [],_x000D_ "touchpoints": null,_x000D_ "last_touch": null,_x000D_ "geo": {_x000D_ "lon": -73.1962,_x000D_ "lat": 41.1854_x000D_ },_x000D_ "timestamp": "0001-01-01T00:00:00"_x000D_ } | E9: 0 | F9: 1 | G9: 1505326 | H9: 1 | I9: 45922.523 | K9: 1720068 | L9: 1 | M9: 773 | N9: 45922.523 | P9: Fox Home Protection Plan | Q9: 0 | R9: 4035180260 | S9: 2 | T9: 2026
A10: 2039215879 | B10: 46072.669 | C10: {_x000D_ "id": 4035349166,_x000D_ "sid": "log-call-no-answer-4789af6beac2f623",_x000D_ "account_id": 441826,_x000D_ "name": "Katie Cingari",_x000D_ "cnam": "Katie Cingari",_x000D_ "search": "",_x000D_ "referrer": "",_x000D_ "visitor_sid": "",_x000D_ "location": "",_x000D_ "source": "Sandbox",_x000D_ "source_id": 1814974,_x000D_ "source_sid": "TSOF6FC2D2594D22C5288F2F91D669A9D5B9BE7FEE3C6EF44F4A9EA1A63913ECD83",_x000D_ "tgid": 5681974,_x000D_ "likelihood": null,_x000D_ "duration": 0,_x000D_ "direction": "form",_x000D_ "talk_time": 0,_x000D_ "ring_time": 0,_x000D_ "hold_time": 0,_x000D_ "wait_time": 0,_x000D_ "parent_id": null,_x000D_ "email": "katie.cingari@gmail.com",_x000D_ "street": null,_x000D_ "city": null,_x000D_ "state": null,_x000D_ "country": null,_x000D_ "postal_code": "06901",_x000D_ "called_at": "2026-02-19 10:03 AM -06:00",_x000D_ "unix_time": 1771520611,_x000D_ "tracking_number_id": 3476065,_x000D_ "tracking_number_sid": "TPNC3C4B23C348AEC2EE54EFD301979CD2EFFBA32881B159867D3F4ED59E6F0B56367EFF2993536685F",_x000D_ "tracking_number": "\u002B14352541043",_x000D_ "tracking_label": "Testing Number",_x000D_ "dial_status": "no-answer",_x000D_ "is_new_caller": true,_x000D_ "indexed_at": 1.7715212E+09,_x000D_ "agent_insights": false,_x000D_ "duration_period": {_x000D_ "gte": 1771520611000,_x000D_ "lte": 1771520611000_x000D_ },_x000D_ "inbound_rate_center": {_x000D_ "country": "US",_x000D_ "prefix": "1",_x000D_ "tollfree": false_x000D_ },_x000D_ "business_number": null,_x000D_ "business_label": null,_x000D_ "receiving_number_id": null,_x000D_ "receiving_number_sid": null,_x000D_ "billed_amount": 0,_x000D_ "billed_at": "0001-01-01T00:00:00",_x000D_ "excluded": false,_x000D_ "redacted": false,_x000D_ "tracking_number_format": "(435) 254-1043",_x000D_ "business_number_format": null,_x000D_ "alternative_number": "2039215879",_x000D_ "tracking_number_bare": "4352541043",_x000D_ "caller_number_format": "(203) 921-5879",_x000D_ "caller_number_complete": "\u002B12039215879",_x000D_ "caller_number_bare": "2039215879",_x000D_ "caller_number": "\u002B12039215879",_x000D_ "caller_number_split": [_x000D_ "1",_x000D_ "203",_x000D_ "921",_x000D_ "5879"_x000D_ ],_x000D_ "contact_number": "\u002B12039215879",_x000D_ "visitor": false,_x000D_ "call_path": [_x000D_ {_x000D_ "route_name": "_OnHangup_CallSync",_x000D_ "route_id": "640990",_x000D_ "route_type": "RoutingRule",_x000D_ "started_at": "2026-02-19T10:03:33Z"_x000D_ }_x000D_ ],_x000D_ "left_talk_time": 0,_x000D_ "right_talk_time": 0,_x000D_ "transfers": [],_x000D_ "call_status": "completed",_x000D_ "status": "completed",_x000D_ "spotted": [],_x000D_ "salesforce": {},_x000D_ "audio": null,_x000D_ "is_s3_link": false,_x000D_ "callbacks": [],_x000D_ "emails": [],_x000D_ "day": "Thursday",_x000D_ "month": "February",_x000D_ "hour": "10AM",_x000D_ "paid": {_x000D_ "source": null,_x000D_ "medium": null_x000D_ },_x000D_ "ga": {_x000D_ "cid": "441826.4035349166",_x000D_ "ga4": []_x000D_ },_x000D_ "tag_list": [],_x000D_ "latitude": 41.0529,_x000D_ "longitude": -73.5375,_x000D_ "extended_lookup_on": true,_x000D_ "form": {_x000D_ "number_to_call": "log-call-no-answer-96669d4871939d13",_x000D_ "customer_number_to_dial": "\u002B12039215879",_x000D_ "name": "Katie Cingari",_x000D_ "email": "katie.cingari@gmail.com",_x000D_ "trackback_id": "trackback-441826.1771520611.7475693",_x000D_ "form_id": 213071,_x000D_ "form_name": "Contact Us",_x000D_ "custom": [_x000D_ {_x000D_ "label": "Referral Source",_x000D_ "value": "",_x000D_ "id": "referral_source"_x000D_ },_x000D_ {_x000D_ "label": "UTM Source",_x000D_ "value": "",_x000D_ "id": "utm_source"_x000D_ },_x000D_ {_x000D_ "label": "UTM Medium",_x000D_ "value": "",_x000D_ "id": "utm_medium"_x000D_ },_x000D_ {_x000D_ "label": "UTM Campaign",_x000D_ "value": "",_x000D_ "id": "utm_campaign"_x000D_ },_x000D_ {_x000D_ "label": "UTM Term",_x000D_ "value": "",_x000D_ "id": "utm_term"_x000D_ },_x000D_ {_x000D_ "label": "UTM Content",_x000D_ "value": "",_x000D_ "id": "utm_content"_x000D_ }_x000D_ ]_x000D_ },_x000D_ "legs": [],_x000D_ "touchpoints": null,_x000D_ "last_touch": null,_x000D_ "geo": {_x000D_ "lon": -73.5375,_x000D_ "lat": 41.0529_x000D_ },_x000D_ "timestamp": "0001-01-01T00:00:00"_x000D_ } | E10: 0 | F10: 1 | G10: 1364243 | H10: 1 | I10: 45776.536 | K10: 1529412 | L10: 1 | M10: 998 | N10: 45776.536 | P10: Fox Home Protection Plan | Q10: 0 | R10: 4035349166 | S10: 2 | T10: 2026
A11: 2072056930 | B11: 46072.103 | C11: {_x000D_ "id": 4034476589,_x000D_ "sid": "log-call-no-answer-2ae19e31f0028e67",_x000D_ "account_id": 441826,_x000D_ "name": "Quinn Cardale",_x000D_ "cnam": "Quinn Cardale",_x000D_ "search": "",_x000D_ "referrer": "",_x000D_ "visitor_sid": "",_x000D_ "location": "",_x000D_ "source": "Sandbox",_x000D_ "source_id": 1814974,_x000D_ "source_sid": "TSOF6FC2D2594D22C5288F2F91D669A9D5B9BE7FEE3C6EF44F4A9EA1A63913ECD83",_x000D_ "tgid": 5681974,_x000D_ "likelihood": null,_x000D_ "duration": 0,_x000D_ "direction": "form",_x000D_ "talk_time": 0,_x000D_ "ring_time": 0,_x000D_ "hold_time": 0,_x000D_ "wait_time": 0,_x000D_ "parent_id": null,_x000D_ "email": "quentinbcardale@icloud.com",_x000D_ "street": null,_x000D_ "city": null,_x000D_ "state": null,_x000D_ "country": null,_x000D_ "postal_code": "04005",_x000D_ "called_at": "2026-02-18 08:29 PM -06:00",_x000D_ "unix_time": 1771471786,_x000D_ "tracking_number_id": 3476065,_x000D_ "tracking_number_sid": "TPNC3C4B23C348AEC2EE54EFD301979CD2EFFBA32881B159867D3F4ED59E6F0B56367EFF2993536685F",_x000D_ "tracking_number": "\u002B14352541043",_x000D_ "tracking_label": "Testing Number",_x000D_ "dial_status": "no-answer",_x000D_ "is_new_caller": true,_x000D_ "indexed_at": 1.7714724E+09,_x000D_ "agent_insights": false,_x000D_ "duration_period": {_x000D_ "gte": 1771471786000,_x000D_ "lte": 1771471786000_x000D_ },_x000D_ "inbound_rate_center": {_x000D_ "country": "US",_x000D_ "prefix": "1",_x000D_ "tollfree": false_x000D_ },_x000D_ "business_number": null,_x000D_ "business_label": null,_x000D_ "receiving_number_id": null,_x000D_ "receiving_number_sid": null,_x000D_ "billed_amount": 0,_x000D_ "billed_at": "0001-01-01T00:00:00",_x000D_ "excluded": false,_x000D_ "redacted": false,_x000D_ "tracking_number_format": "(435) 254-1043",_x000D_ "business_number_format": null,_x000D_ "alternative_number": "2072056930",_x000D_ "tracking_number_bare": "4352541043",_x000D_ "caller_number_format": "(207) 205-6930",_x000D_ "caller_number_complete": "\u002B12072056930",_x000D_ "caller_number_bare": "2072056930",_x000D_ "caller_number": "\u002B12072056930",_x000D_ "caller_number_split": [_x000D_ "1",_x000D_ "207",_x000D_ "205",_x000D_ "6930"_x000D_ ],_x000D_ "contact_number": "\u002B12072056930",_x000D_ "visitor": false,_x000D_ "call_path": [_x000D_ {_x000D_ "route_name": "_OnHangup_CallSync",_x000D_ "route_id": "640990",_x000D_ "route_type": "RoutingRule",_x000D_ "started_at": "2026-02-18T20:29:47Z"_x000D_ }_x000D_ ],_x000D_ "left_talk_time": 0,_x000D_ "right_talk_time": 0,_x000D_ "transfers": [],_x000D_ "call_status": "completed",_x000D_ "status": "completed",_x000D_ "spotted": [],_x000D_ "salesforce": {},_x000D_ "audio": null,_x000D_ "is_s3_link": false,_x000D_ "callbacks": [],_x000D_ "emails": [],_x000D_ "day": "Wednesday",_x000D_ "month": "February",_x000D_ "hour": "08PM",_x000D_ "paid": {_x000D_ "source": null,_x000D_ "medium": null_x000D_ },_x000D_ "ga": {_x000D_ "cid": "441826.4034476589",_x000D_ "ga4": []_x000D_ },_x000D_ "tag_list": [],_x000D_ "latitude": 43.494,_x000D_ "longitude": -70.4594,_x000D_ "extended_lookup_on": true,_x000D_ "form": {_x000D_ "number_to_call": "log-call-no-answer-6ee4b4744bc16bdc",_x000D_ "customer_number_to_dial": "\u002B12072056930",_x000D_ "name": "Quinn Cardale",_x000D_ "email": "quentinbcardale@icloud.com",_x000D_ "trackback_id": "trackback-441826.1771471786.39154",_x000D_ "form_id": 213071,_x000D_ "form_name": "Contact Us",_x000D_ "custom": [_x000D_ {_x000D_ "label": "Referral Source",_x000D_ "value": "",_x000D_ "id": "referral_source"_x000D_ },_x000D_ {_x000D_ "label": "UTM Source",_x000D_ "value": "",_x000D_ "id": "utm_source"_x000D_ },_x000D_ {_x000D_ "label": "UTM Medium",_x000D_ "value": "",_x000D_ "id": "utm_medium"_x000D_ },_x000D_ {_x000D_ "label": "UTM Campaign",_x000D_ "value": "",_x000D_ "id": "utm_campaign"_x000D_ },_x000D_ {_x000D_ "label": "UTM Term",_x000D_ "value": "",_x000D_ "id": "utm_term"_x000D_ },_x000D_ {_x000D_ "label": "UTM Content",_x000D_ "value": "",_x000D_ "id": "utm_content"_x000D_ }_x000D_ ]_x000D_ },_x000D_ "legs": [],_x000D_ "touchpoints": null,_x000D_ "last_touch": null,_x000D_ "geo": {_x000D_ "lon": -70.4594,_x000D_ "lat": 43.494_x000D_ },_x000D_ "timestamp": "0001-01-01T00:00:00"_x000D_ } | E11: 1 | F11: 1 | G11: 1523517 | H11: 1 | I11: 46072.814 | K11: 1769803 | L11: 1 | M11: 996 | N11: 46072.814 | P11: Fox Home Protection Plan | Q11: 1 | R11: 4034476589 | S11: 2 | T11: 2026
A12: 2073754558 | B12: 46073.701 | C12: {_x000D_ "id": 4038213596,_x000D_ "sid": "log-call-no-answer-881e1159a979bb6c",_x000D_ "account_id": 441826,_x000D_ "name": "DEBORAH Meroff",_x000D_ "cnam": "DEBORAH Meroff",_x000D_ "search": "",_x000D_ "referrer": "",_x000D_ "visitor_sid": "",_x000D_ "location": "",_x000D_ "source": "Sandbox",_x000D_ "source_id": 1814974,_x000D_ "source_sid": "TSOF6FC2D2594D22C5288F2F91D669A9D5B9BE7FEE3C6EF44F4A9EA1A63913ECD83",_x000D_ "tgid": 5681974,_x000D_ "likelihood": null,_x000D_ "duration": 0,_x000D_ "direction": "form",_x000D_ "talk_time": 0,_x000D_ "ring_time": 0,_x000D_ "hold_time": 0,_x000D_ "wait_time": 0,_x000D_ "parent_id": null,_x000D_ "email": "mainewrtr48@gmail.com",_x000D_ "street": null,_x000D_ "city": "Sabattus",_x000D_ "state": "ME",_x000D_ "country": null,_x000D_ "postal_code": "04280",_x000D_ "called_at": "2026-02-20 10:50 AM -06:00",_x000D_ "unix_time": 1771609820,_x000D_ "tracking_number_id": 3476065,_x000D_ "tracking_number_sid": "TPNC3C4B23C348AEC2EE54EFD301979CD2EFFBA32881B159867D3F4ED59E6F0B56367EFF2993536685F",_x000D_ "tracking_number": "\u002B14352541043",_x000D_ "tracking_label": "Testing Number",_x000D_ "dial_status": "no-answer",_x000D_ "is_new_caller": true,_x000D_ "indexed_at": 1.7716104E+09,_x000D_ "agent_insights": false,_x000D_ "duration_period": {_x000D_ "gte": 1771609820000,_x000D_ "lte": 1771609820000_x000D_ },_x000D_ "inbound_rate_center": {_x000D_ "country": "US",_x000D_ "prefix": "1",_x000D_ "tollfree": false_x000D_ },_x000D_ "business_number": null,_x000D_ "business_label": null,_x000D_ "receiving_number_id": null,_x000D_ "receiving_number_sid": null,_x000D_ "billed_amount": 0,_x000D_ "billed_at": "0001-01-01T00:00:00",_x000D_ "excluded": false,_x000D_ "redacted": false,_x000D_ "tracking_number_format": "(435) 254-1043",_x000D_ "business_number_format": null,_x000D_ "alternative_number": "2073754558",_x000D_ "tracking_number_bare": "4352541043",_x000D_ "caller_number_format": "(207) 375-4558",_x000D_ "caller_number_complete": "\u002B12073754558",_x000D_ "caller_number_bare": "2073754558",_x000D_ "caller_number": "\u002B12073754558",_x000D_ "caller_number_split": [_x000D_ "1",_x000D_ "207",_x000D_ "375",_x000D_ "4558"_x000D_ ],_x000D_ "contact_number": "\u002B12073754558",_x000D_ "visitor": false,_x000D_ "call_path": [_x000D_ {_x000D_ "route_name": "_OnHangup_CallSync",_x000D_ "route_id": "640990",_x000D_ "route_type": "RoutingRule",_x000D_ "started_at": "2026-02-20T10:50:21Z"_x000D_ }_x000D_ ],_x000D_ "left_talk_time": 0,_x000D_ "right_talk_time": 0,_x000D_ "transfers": [],_x000D_ "call_status": "completed",_x000D_ "status": "completed",_x000D_ "spotted": [],_x000D_ "salesforce": {},_x000D_ "audio": null,_x000D_ "is_s3_link": false,_x000D_ "callbacks": [],_x000D_ "emails": [],_x000D_ "day": "Friday",_x000D_ "month": "February",_x000D_ "hour": "10AM",_x000D_ "paid": {_x000D_ "source": null,_x000D_ "medium": null_x000D_ },_x000D_ "ga": {_x000D_ "cid": "441826.4038213596",_x000D_ "ga4": []_x000D_ },_x000D_ "tag_list": [],_x000D_ "latitude": 44.1186,_x000D_ "longitude": -70.1062,_x000D_ "extended_lookup_on": true,_x000D_ "form": {_x000D_ "number_to_call": "log-call-no-answer-245efee4b3374c59",_x000D_ "customer_number_to_dial": "\u002B12073754558",_x000D_ "name": "DEBORAH Meroff",_x000D_ "email": "mainewrtr48@gmail.com",_x000D_ "trackback_id": "trackback-441826.1771609820.4256136",_x000D_ "form_id": 213071,_x000D_ "form_name": "Contact Us",_x000D_ "custom": [_x000D_ {_x000D_ "label": "Referral Source",_x000D_ "value": "",_x000D_ "id": "referral_source"_x000D_ },_x000D_ {_x000D_ "label": "UTM Source",_x000D_ "value": "",_x000D_ "id": "utm_source"_x000D_ },_x000D_ {_x000D_ "label": "UTM Medium",_x000D_ "value": "",_x000D_ "id": "utm_medium"_x000D_ },_x000D_ {_x000D_ "label": "UTM Campaign",_x000D_ "value": "",_x000D_ "id": "utm_campaign"_x000D_ },_x000D_ {_x000D_ "label": "UTM Term",_x000D_ "value": "",_x000D_ "id": "utm_term"_x000D_ },_x000D_ {_x000D_ "label": "UTM Content",_x000D_ "value": "",_x000D_ "id": "utm_content"_x000D_ }_x000D_ ]_x000D_ },_x000D_ "legs": [],_x000D_ "touchpoints": null,_x000D_ "last_touch": null,_x000D_ "geo": {_x000D_ "lon": -70.1062,_x000D_ "lat": 44.1186_x000D_ },_x000D_ "timestamp": "0001-01-01T00:00:00"_x000D_ } | E12: 0 | F12: 1 | G12: 1473005 | H12: 1 | I12: 45871.708 | K12: 1673489 | L12: 1 | M12: 759 | N12: 45871.715 | P12: Fox Home Protection Plan | Q12: 0 | R12: 4038213596 | S12: 2 | T12: 2026
A13: 2076498302 | B13: 46074.877 | C13: {_x000D_ "id": 4040306234,_x000D_ "sid": "log-call-no-answer-b2366cfc032426ed",_x000D_ "account_id": 441826,_x000D_ "name": "Sierra Linnell",_x000D_ "cnam": "Sierra Linnell",_x000D_ "search": "",_x000D_ "referrer": "",_x000D_ "visitor_sid": "",_x000D_ "location": "",_x000D_ "source": "Sandbox",_x000D_ "source_id": 1814974,_x000D_ "source_sid": "TSOF6FC2D2594D22C5288F2F91D669A9D5B9BE7FEE3C6EF44F4A9EA1A63913ECD83",_x000D_ "tgid": 5681974,_x000D_ "likelihood": null,_x000D_ "duration": 0,_x000D_ "direction": "form",_x000D_ "talk_time": 0,_x000D_ "ring_time": 0,_x000D_ "hold_time": 0,_x000D_ "wait_time": 0,_x000D_ "parent_id": null,_x000D_ "email": "sierradawn201494@gmail.com",_x000D_ "street": null,_x000D_ "city": null,_x000D_ "state": null,_x000D_ "country": null,_x000D_ "postal_code": "04901",_x000D_ "called_at": "2026-02-21 03:03 PM -06:00",_x000D_ "unix_time": 1771711383,_x000D_ "tracking_number_id": 3476065,_x000D_ "tracking_number_sid": "TPNC3C4B23C348AEC2EE54EFD301979CD2EFFBA32881B159867D3F4ED59E6F0B56367EFF2993536685F",_x000D_ "tracking_number": "\u002B14352541043",_x000D_ "tracking_label": "Testing Number",_x000D_ "dial_status": "no-answer",_x000D_ "is_new_caller": true,_x000D_ "indexed_at": 1.771712E+09,_x000D_ "agent_insights": false,_x000D_ "duration_period": {_x000D_ "gte": 1771711383000,_x000D_ "lte": 1771711383000_x000D_ },_x000D_ "inbound_rate_center": {_x000D_ "country": "US",_x000D_ "prefix": "1",_x000D_ "tollfree": false_x000D_ },_x000D_ "business_number": null,_x000D_ "business_label": null,_x000D_ "receiving_number_id": null,_x000D_ "receiving_number_sid": null,_x000D_ "billed_amount": 0,_x000D_ "billed_at": "0001-01-01T00:00:00",_x000D_ "excluded": false,_x000D_ "redacted": false,_x000D_ "tracking_number_format": "(435) 254-1043",_x000D_ "business_number_format": null,_x000D_ "alternative_number": "2076498302",_x000D_ "tracking_number_bare": "4352541043",_x000D_ "caller_number_format": "(207) 649-8302",_x000D_ "caller_number_complete": "\u002B12076498302",_x000D_ "caller_number_bare": "2076498302",_x000D_ "caller_number": "\u002B12076498302",_x000D_ "caller_number_split": [_x000D_ "1",_x000D_ "207",_x000D_ "649",_x000D_ "8302"_x000D_ ],_x000D_ "contact_number": "\u002B12076498302",_x000D_ "visitor": false,_x000D_ "call_path": [_x000D_ {_x000D_ "route_name": "_OnHangup_CallSync",_x000D_ "route_id": "640990",_x000D_ "route_type": "RoutingRule",_x000D_ "started_at": "2026-02-21T15:03:04Z"_x000D_ }_x000D_ ],_x000D_ "left_talk_time": 0,_x000D_ "right_talk_time": 0,_x000D_ "transfers": [],_x000D_ "call_status": "completed",_x000D_ "status": "completed",_x000D_ "spotted": [],_x000D_ "salesforce": {},_x000D_ "audio": null,_x000D_ "is_s3_link": false,_x000D_ "callbacks": [],_x000D_ "emails": [],_x000D_ "day": "Saturday",_x000D_ "month": "February",_x000D_ "hour": "03PM",_x000D_ "paid": {_x000D_ "source": null,_x000D_ "medium": null_x000D_ },_x000D_ "ga": {_x000D_ "cid": "441826.4040306234",_x000D_ "ga4": []_x000D_ },_x000D_ "tag_list": [],_x000D_ "latitude": 44.5528,_x000D_ "longitude": -69.63,_x000D_ "extended_lookup_on": true,_x000D_ "form": {_x000D_ "number_to_call": "log-call-no-answer-c372eaf35cdccafa",_x000D_ "customer_number_to_dial": "\u002B12076498302",_x000D_ "name": "Sierra Linnell",_x000D_ "email": "sierradawn201494@gmail.com",_x000D_ "trackback_id": "trackback-441826.1771711383.3176322",_x000D_ "form_id": 213071,_x000D_ "form_name": "Contact Us",_x000D_ "custom": [_x000D_ {_x000D_ "label": "Referral Source",_x000D_ "value": "",_x000D_ "id": "referral_source"_x000D_ },_x000D_ {_x000D_ "label": "UTM Source",_x000D_ "value": "",_x000D_ "id": "utm_source"_x000D_ },_x000D_ {_x000D_ "label": "UTM Medium",_x000D_ "value": "",_x000D_ "id": "utm_medium"_x000D_ },_x000D_ {_x000D_ "label": "UTM Campaign",_x000D_ "value": "",_x000D_ "id": "utm_campaign"_x000D_ },_x000D_ {_x000D_ "label": "UTM Term",_x000D_ "value": "",_x000D_ "id": "utm_term"_x000D_ },_x000D_ {_x000D_ "label": "UTM Content",_x000D_ "value": "",_x000D_ "id": "utm_content"_x000D_ }_x000D_ ]_x000D_ },_x000D_ "legs": [],_x000D_ "touchpoints": null,_x000D_ "last_touch": null,_x000D_ "geo": {_x000D_ "lon": -69.63,_x000D_ "lat": 44.5528_x000D_ },_x000D_ "timestamp": "0001-01-01T00:00:00"_x000D_ } | E13: 0 | F13: 1 | G13: 1523780 | I13: 46076.612 | J13: 1775221076000 | Q13: 0 | R13: 4040306234 | S13: 2 | T13: 2026
