Workbook

Sheet Branch View
H1: Choose Branch from dropdown: | I1: Albany - NY
A2: Year | B2: Month | C2: Month | D2: IM Sales | E2: IM Sales CV | F2: IM Cancels | G2: IM Cancels CV | H2: IM Sales/IM Cancels | I2: IM Sale CV / IM Cancel CV | K2: All Sales | L2: All Sales CV | M2: Cancels | N2: Cancelled CV | O2: All sales/Cancels | P2: All sale CV / Cancel CV
A3: 2022 | B3: 1 | C3: January | D3: =SUMIFS('Sales csv'!$E:$E,'Sales csv'!$A:$A,'Branch View'!$A3,'Sales csv'!$B:$B,'Branch View'!$B3,'Sales csv'!$D:$D,'Branch View'!$I$1) -> 12 | E3: =SUMIFS('Sales csv'!$F:$F,'Sales csv'!$A:$A,'Branch View'!$A3,'Sales csv'!$B:$B,'Branch View'!$B3,'Sales csv'!$D:$D,'Branch View'!$I$1) -> 9802.53 | F3: =SUMIFS('IM Cancels csv'!$E:$E,'IM Cancels csv'!$A:$A,'Branch View'!$A3,'IM Cancels csv'!$B:$B,'Branch View'!$B3,'IM Cancels csv'!$D:$D,'Branch View'!$I$1) -> 17 | G3: =SUMIFS('IM Cancels csv'!$F:$F,'IM Cancels csv'!$A:$A,'Branch View'!$A3,'IM Cancels csv'!$B:$B,'Branch View'!$B3,'IM Cancels csv'!$D:$D,'Branch View'!$I$1) -> 11972.52 | H3: =D3/F3 -> 0.70588235 | I3: =E3/G3 -> 0.81875244 | K3: =SUMIFS('All Sales csv'!$E:$E,'All Sales csv'!$A:$A,'Branch View'!$A3,'All Sales csv'!$B:$B,'Branch View'!$B3,'All Sales csv'!$D:$D,'Branch View'!$I$1) -> 31 | L3: =SUMIFS('All Sales csv'!$F:$F,'All Sales csv'!$A:$A,'Branch View'!$A3,'All Sales csv'!$B:$B,'Branch View'!$B3,'All Sales csv'!$D:$D,'Branch View'!$I$1) -> 20247.7 | M3: =SUMIFS('Cancels csv'!E:E,'Cancels csv'!A:A,'Branch View'!A3,'Cancels csv'!B:B,'Branch View'!B3,'Cancels csv'!D:D,'Branch View'!$I$1) -> 100 | N3: =SUMIFS('Cancels csv'!F:F,'Cancels csv'!A:A,'Branch View'!A3,'Cancels csv'!B:B,'Branch View'!B3,'Cancels csv'!D:D,'Branch View'!$I$1) -> 71458.5 | O3: =K3/M3 -> 0.31 | P3: =L3/N3 -> 0.28334908
A4: 2022 | B4: 2 | C4: February | D4: =SUMIFS('Sales csv'!E:E,'Sales csv'!A:A,'Branch View'!A4,'Sales csv'!B:B,'Branch View'!B4,'Sales csv'!D:D,'Branch View'!$I$1) -> 20 | E4: =SUMIFS('Sales csv'!F:F,'Sales csv'!A:A,'Branch View'!A4,'Sales csv'!B:B,'Branch View'!B4,'Sales csv'!D:D,'Branch View'!$I$1) -> 17612.53 | F4: =SUMIFS('IM Cancels csv'!$E:$E,'IM Cancels csv'!$A:$A,'Branch View'!$A4,'IM Cancels csv'!$B:$B,'Branch View'!$B4,'IM Cancels csv'!$D:$D,'Branch View'!$I$1) -> 10 | G4: =SUMIFS('IM Cancels csv'!$F:$F,'IM Cancels csv'!$A:$A,'Branch View'!$A4,'IM Cancels csv'!$B:$B,'Branch View'!$B4,'IM Cancels csv'!$D:$D,'Branch View'!$I$1) -> 7456.84 | H4: =D4/F4 -> 2 | I4: =E4/G4 -> 2.3619295 | K4: =SUMIFS('All Sales csv'!$E:$E,'All Sales csv'!$A:$A,'Branch View'!$A4,'All Sales csv'!$B:$B,'Branch View'!$B4,'All Sales csv'!$D:$D,'Branch View'!$I$1) -> 38 | L4: =SUMIFS('All Sales csv'!$F:$F,'All Sales csv'!$A:$A,'Branch View'!$A4,'All Sales csv'!$B:$B,'Branch View'!$B4,'All Sales csv'!$D:$D,'Branch View'!$I$1) -> 29719.03 | M4: =SUMIFS('Cancels csv'!E:E,'Cancels csv'!A:A,'Branch View'!A4,'Cancels csv'!B:B,'Branch View'!B4,'Cancels csv'!D:D,'Branch View'!$I$1) -> 48 | N4: =SUMIFS('Cancels csv'!F:F,'Cancels csv'!A:A,'Branch View'!A4,'Cancels csv'!B:B,'Branch View'!B4,'Cancels csv'!D:D,'Branch View'!$I$1) -> 37281.54 | O4: =K4/M4 -> 0.79166667 | P4: =L4/N4 -> 0.79715135
A5: 2022 | B5: 3 | C5: March | D5: =SUMIFS('Sales csv'!E:E,'Sales csv'!A:A,'Branch View'!A5,'Sales csv'!B:B,'Branch View'!B5,'Sales csv'!D:D,'Branch View'!$I$1) -> 28 | E5: =SUMIFS('Sales csv'!F:F,'Sales csv'!A:A,'Branch View'!A5,'Sales csv'!B:B,'Branch View'!B5,'Sales csv'!D:D,'Branch View'!$I$1) -> 20632.84 | F5: =SUMIFS('IM Cancels csv'!$E:$E,'IM Cancels csv'!$A:$A,'Branch View'!$A5,'IM Cancels csv'!$B:$B,'Branch View'!$B5,'IM Cancels csv'!$D:$D,'Branch View'!$I$1) -> 16 | G5: =SUMIFS('IM Cancels csv'!$F:$F,'IM Cancels csv'!$A:$A,'Branch View'!$A5,'IM Cancels csv'!$B:$B,'Branch View'!$B5,'IM Cancels csv'!$D:$D,'Branch View'!$I$1) -> 10572.52 | H5: =D5/F5 -> 1.75 | I5: =E5/G5 -> 1.9515537 | K5: =SUMIFS('All Sales csv'!$E:$E,'All Sales csv'!$A:$A,'Branch View'!$A5,'All Sales csv'!$B:$B,'Branch View'!$B5,'All Sales csv'!$D:$D,'Branch View'!$I$1) -> 53 | L5: =SUMIFS('All Sales csv'!$F:$F,'All Sales csv'!$A:$A,'Branch View'!$A5,'All Sales csv'!$B:$B,'Branch View'!$B5,'All Sales csv'!$D:$D,'Branch View'!$I$1) -> 36927.34 | M5: =SUMIFS('Cancels csv'!E:E,'Cancels csv'!A:A,'Branch View'!A5,'Cancels csv'!B:B,'Branch View'!B5,'Cancels csv'!D:D,'Branch View'!$I$1) -> 112 | N5: =SUMIFS('Cancels csv'!F:F,'Cancels csv'!A:A,'Branch View'!A5,'Cancels csv'!B:B,'Branch View'!B5,'Cancels csv'!D:D,'Branch View'!$I$1) -> 75930.16 | O5: =K5/M5 -> 0.47321429 | P5: =L5/N5 -> 0.48633297
A6: 2022 | B6: 4 | C6: April | D6: =SUMIFS('Sales csv'!E:E,'Sales csv'!A:A,'Branch View'!A6,'Sales csv'!B:B,'Branch View'!B6,'Sales csv'!D:D,'Branch View'!$I$1) -> 50 | E6: =SUMIFS('Sales csv'!F:F,'Sales csv'!A:A,'Branch View'!A6,'Sales csv'!B:B,'Branch View'!B6,'Sales csv'!D:D,'Branch View'!$I$1) -> 36043.13 | F6: =SUMIFS('IM Cancels csv'!$E:$E,'IM Cancels csv'!$A:$A,'Branch View'!$A6,'IM Cancels csv'!$B:$B,'Branch View'!$B6,'IM Cancels csv'!$D:$D,'Branch View'!$I$1) -> 24 | G6: =SUMIFS('IM Cancels csv'!$F:$F,'IM Cancels csv'!$A:$A,'Branch View'!$A6,'IM Cancels csv'!$B:$B,'Branch View'!$B6,'IM Cancels csv'!$D:$D,'Branch View'!$I$1) -> 16095.43 | H6: =D6/F6 -> 2.0833333 | I6: =E6/G6 -> 2.2393394 | K6: =SUMIFS('All Sales csv'!$E:$E,'All Sales csv'!$A:$A,'Branch View'!$A6,'All Sales csv'!$B:$B,'Branch View'!$B6,'All Sales csv'!$D:$D,'Branch View'!$I$1) -> 98 | L6: =SUMIFS('All Sales csv'!$F:$F,'All Sales csv'!$A:$A,'Branch View'!$A6,'All Sales csv'!$B:$B,'Branch View'!$B6,'All Sales csv'!$D:$D,'Branch View'!$I$1) -> 76270.02 | M6: =SUMIFS('Cancels csv'!E:E,'Cancels csv'!A:A,'Branch View'!A6,'Cancels csv'!B:B,'Branch View'!B6,'Cancels csv'!D:D,'Branch View'!$I$1) -> 132 | N6: =SUMIFS('Cancels csv'!F:F,'Cancels csv'!A:A,'Branch View'!A6,'Cancels csv'!B:B,'Branch View'!B6,'Cancels csv'!D:D,'Branch View'!$I$1) -> 90594.77 | O6: =K6/M6 -> 0.74242424 | P6: =L6/N6 -> 0.84188105
A7: 2022 | B7: 5 | C7: May | D7: =SUMIFS('Sales csv'!E:E,'Sales csv'!A:A,'Branch View'!A7,'Sales csv'!B:B,'Branch View'!B7,'Sales csv'!D:D,'Branch View'!$I$1) -> 78 | E7: =SUMIFS('Sales csv'!F:F,'Sales csv'!A:A,'Branch View'!A7,'Sales csv'!B:B,'Branch View'!B7,'Sales csv'!D:D,'Branch View'!$I$1) -> 59064.24 | F7: =SUMIFS('IM Cancels csv'!$E:$E,'IM Cancels csv'!$A:$A,'Branch View'!$A7,'IM Cancels csv'!$B:$B,'Branch View'!$B7,'IM Cancels csv'!$D:$D,'Branch View'!$I$1) -> 25 | G7: =SUMIFS('IM Cancels csv'!$F:$F,'IM Cancels csv'!$A:$A,'Branch View'!$A7,'IM Cancels csv'!$B:$B,'Branch View'!$B7,'IM Cancels csv'!$D:$D,'Branch View'!$I$1) -> 17950.13 | H7: =D7/F7 -> 3.12 | I7: =E7/G7 -> 3.2904631 | K7: =SUMIFS('All Sales csv'!$E:$E,'All Sales csv'!$A:$A,'Branch View'!$A7,'All Sales csv'!$B:$B,'Branch View'!$B7,'All Sales csv'!$D:$D,'Branch View'!$I$1) -> 567 | L7: =SUMIFS('All Sales csv'!$F:$F,'All Sales csv'!$A:$A,'Branch View'!$A7,'All Sales csv'!$B:$B,'Branch View'!$B7,'All Sales csv'!$D:$D,'Branch View'!$I$1) -> 518551.06 | M7: =SUMIFS('Cancels csv'!E:E,'Cancels csv'!A:A,'Branch View'!A7,'Cancels csv'!B:B,'Branch View'!B7,'Cancels csv'!D:D,'Branch View'!$I$1) -> 159 | N7: =SUMIFS('Cancels csv'!F:F,'Cancels csv'!A:A,'Branch View'!A7,'Cancels csv'!B:B,'Branch View'!B7,'Cancels csv'!D:D,'Branch View'!$I$1) -> 120354.45 | O7: =K7/M7 -> 3.5660377 | P7: =L7/N7 -> 4.3085325
A8: 2022 | B8: 6 | C8: June | D8: =SUMIFS('Sales csv'!E:E,'Sales csv'!A:A,'Branch View'!A8,'Sales csv'!B:B,'Branch View'!B8,'Sales csv'!D:D,'Branch View'!$I$1) -> 50 | E8: =SUMIFS('Sales csv'!F:F,'Sales csv'!A:A,'Branch View'!A8,'Sales csv'!B:B,'Branch View'!B8,'Sales csv'!D:D,'Branch View'!$I$1) -> 35223.34 | F8: =SUMIFS('IM Cancels csv'!$E:$E,'IM Cancels csv'!$A:$A,'Branch View'!$A8,'IM Cancels csv'!$B:$B,'Branch View'!$B8,'IM Cancels csv'!$D:$D,'Branch View'!$I$1) -> 38 | G8: =SUMIFS('IM Cancels csv'!$F:$F,'IM Cancels csv'!$A:$A,'Branch View'!$A8,'IM Cancels csv'!$B:$B,'Branch View'!$B8,'IM Cancels csv'!$D:$D,'Branch View'!$I$1) -> 26090.52 | H8: =D8/F8 -> 1.3157895 | I8: =E8/G8 -> 1.3500436 | K8: =SUMIFS('All Sales csv'!$E:$E,'All Sales csv'!$A:$A,'Branch View'!$A8,'All Sales csv'!$B:$B,'Branch View'!$B8,'All Sales csv'!$D:$D,'Branch View'!$I$1) -> 411 | L8: =SUMIFS('All Sales csv'!$F:$F,'All Sales csv'!$A:$A,'Branch View'!$A8,'All Sales csv'!$B:$B,'Branch View'!$B8,'All Sales csv'!$D:$D,'Branch View'!$I$1) -> 381825.46 | M8: =SUMIFS('Cancels csv'!E:E,'Cancels csv'!A:A,'Branch View'!A8,'Cancels csv'!B:B,'Branch View'!B8,'Cancels csv'!D:D,'Branch View'!$I$1) -> 240 | N8: =SUMIFS('Cancels csv'!F:F,'Cancels csv'!A:A,'Branch View'!A8,'Cancels csv'!B:B,'Branch View'!B8,'Cancels csv'!D:D,'Branch View'!$I$1) -> 195324.43 | O8: =K8/M8 -> 1.7125 | P8: =L8/N8 -> 1.954827
A9: 2022 | B9: 7 | C9: July | D9: =SUMIFS('Sales csv'!E:E,'Sales csv'!A:A,'Branch View'!A9,'Sales csv'!B:B,'Branch View'!B9,'Sales csv'!D:D,'Branch View'!$I$1) -> 70 | E9: =SUMIFS('Sales csv'!F:F,'Sales csv'!A:A,'Branch View'!A9,'Sales csv'!B:B,'Branch View'!B9,'Sales csv'!D:D,'Branch View'!$I$1) -> 43537.11 | F9: =SUMIFS('IM Cancels csv'!$E:$E,'IM Cancels csv'!$A:$A,'Branch View'!$A9,'IM Cancels csv'!$B:$B,'Branch View'!$B9,'IM Cancels csv'!$D:$D,'Branch View'!$I$1) -> 43 | G9: =SUMIFS('IM Cancels csv'!$F:$F,'IM Cancels csv'!$A:$A,'Branch View'!$A9,'IM Cancels csv'!$B:$B,'Branch View'!$B9,'IM Cancels csv'!$D:$D,'Branch View'!$I$1) -> 27050.74 | H9: =D9/F9 -> 1.627907 | I9: =E9/G9 -> 1.609461 | K9: =SUMIFS('All Sales csv'!$E:$E,'All Sales csv'!$A:$A,'Branch View'!$A9,'All Sales csv'!$B:$B,'Branch View'!$B9,'All Sales csv'!$D:$D,'Branch View'!$I$1) -> 470 | L9: =SUMIFS('All Sales csv'!$F:$F,'All Sales csv'!$A:$A,'Branch View'!$A9,'All Sales csv'!$B:$B,'Branch View'!$B9,'All Sales csv'!$D:$D,'Branch View'!$I$1) -> 434063.28 | M9: =SUMIFS('Cancels csv'!E:E,'Cancels csv'!A:A,'Branch View'!A9,'Cancels csv'!B:B,'Branch View'!B9,'Cancels csv'!D:D,'Branch View'!$I$1) -> 359 | N9: =SUMIFS('Cancels csv'!F:F,'Cancels csv'!A:A,'Branch View'!A9,'Cancels csv'!B:B,'Branch View'!B9,'Cancels csv'!D:D,'Branch View'!$I$1) -> 216460.87 | O9: =K9/M9 -> 1.3091922 | P9: =L9/N9 -> 2.0052737
A10: 2022 | B10: 8 | C10: August | D10: =SUMIFS('Sales csv'!E:E,'Sales csv'!A:A,'Branch View'!A10,'Sales csv'!B:B,'Branch View'!B10,'Sales csv'!D:D,'Branch View'!$I$1) -> 107 | E10: =SUMIFS('Sales csv'!F:F,'Sales csv'!A:A,'Branch View'!A10,'Sales csv'!B:B,'Branch View'!B10,'Sales csv'!D:D,'Branch View'!$I$1) -> 75716.08 | F10: =SUMIFS('IM Cancels csv'!$E:$E,'IM Cancels csv'!$A:$A,'Branch View'!$A10,'IM Cancels csv'!$B:$B,'Branch View'!$B10,'IM Cancels csv'!$D:$D,'Branch View'!$I$1) -> 57 | G10: =SUMIFS('IM Cancels csv'!$F:$F,'IM Cancels csv'!$A:$A,'Branch View'!$A10,'IM Cancels csv'!$B:$B,'Branch View'!$B10,'IM Cancels csv'!$D:$D,'Branch View'!$I$1) -> 28447.02 | H10: =D10/F10 -> 1.877193 | I10: =E10/G10 -> 2.6616524 | K10: =SUMIFS('All Sales csv'!$E:$E,'All Sales csv'!$A:$A,'Branch View'!$A10,'All Sales csv'!$B:$B,'Branch View'!$B10,'All Sales csv'!$D:$D,'Branch View'!$I$1) -> 282 | L10: =SUMIFS('All Sales csv'!$F:$F,'All Sales csv'!$A:$A,'Branch View'!$A10,'All Sales csv'!$B:$B,'Branch View'!$B10,'All Sales csv'!$D:$D,'Branch View'!$I$1) -> 235680.3 | M10: =SUMIFS('Cancels csv'!E:E,'Cancels csv'!A:A,'Branch View'!A10,'Cancels csv'!B:B,'Branch View'!B10,'Cancels csv'!D:D,'Branch View'!$I$1) -> 268 | N10: =SUMIFS('Cancels csv'!F:F,'Cancels csv'!A:A,'Branch View'!A10,'Cancels csv'!B:B,'Branch View'!B10,'Cancels csv'!D:D,'Branch View'!$I$1) -> 204171.58 | O10: =K10/M10 -> 1.0522388 | P10: =L10/N10 -> 1.1543247
A11: 2022 | B11: 9 | C11: September | D11: =SUMIFS('Sales csv'!E:E,'Sales csv'!A:A,'Branch View'!A11,'Sales csv'!B:B,'Branch View'!B11,'Sales csv'!D:D,'Branch View'!$I$1) -> 46 | E11: =SUMIFS('Sales csv'!F:F,'Sales csv'!A:A,'Branch View'!A11,'Sales csv'!B:B,'Branch View'!B11,'Sales csv'!D:D,'Branch View'!$I$1) -> 30928.04 | F11: =SUMIFS('IM Cancels csv'!$E:$E,'IM Cancels csv'!$A:$A,'Branch View'!$A11,'IM Cancels csv'!$B:$B,'Branch View'!$B11,'IM Cancels csv'!$D:$D,'Branch View'!$I$1) -> 27 | G11: =SUMIFS('IM Cancels csv'!$F:$F,'IM Cancels csv'!$A:$A,'Branch View'!$A11,'IM Cancels csv'!$B:$B,'Branch View'!$B11,'IM Cancels csv'!$D:$D,'Branch View'!$I$1) -> 21684.39 | H11: =D11/F11 -> 1.7037037 | I11: =E11/G11 -> 1.4262813 | K11: =SUMIFS('All Sales csv'!$E:$E,'All Sales csv'!$A:$A,'Branch View'!$A11,'All Sales csv'!$B:$B,'Branch View'!$B11,'All Sales csv'!$D:$D,'Branch View'!$I$1) -> 86 | L11: =SUMIFS('All Sales csv'!$F:$F,'All Sales csv'!$A:$A,'Branch View'!$A11,'All Sales csv'!$B:$B,'Branch View'!$B11,'All Sales csv'!$D:$D,'Branch View'!$I$1) -> 67300.12 | M11: =SUMIFS('Cancels csv'!E:E,'Cancels csv'!A:A,'Branch View'!A11,'Cancels csv'!B:B,'Branch View'!B11,'Cancels csv'!D:D,'Branch View'!$I$1) -> 185 | N11: =SUMIFS('Cancels csv'!F:F,'Cancels csv'!A:A,'Branch View'!A11,'Cancels csv'!B:B,'Branch View'!B11,'Cancels csv'!D:D,'Branch View'!$I$1) -> 155672.54 | O11: =K11/M11 -> 0.46486486 | P11: =L11/N11 -> 0.43231851
A12: 2022 | B12: 10 | C12: October | D12: =SUMIFS('Sales csv'!E:E,'Sales csv'!A:A,'Branch View'!A12,'Sales csv'!B:B,'Branch View'!B12,'Sales csv'!D:D,'Branch View'!$I$1) -> 62 | E12: =SUMIFS('Sales csv'!F:F,'Sales csv'!A:A,'Branch View'!A12,'Sales csv'!B:B,'Branch View'!B12,'Sales csv'!D:D,'Branch View'!$I$1) -> 46742.04 | F12: =SUMIFS('IM Cancels csv'!$E:$E,'IM Cancels csv'!$A:$A,'Branch View'!$A12,'IM Cancels csv'!$B:$B,'Branch View'!$B12,'IM Cancels csv'!$D:$D,'Branch View'!$I$1) -> 59 | G12: =SUMIFS('IM Cancels csv'!$F:$F,'IM Cancels csv'!$A:$A,'Branch View'!$A12,'IM Cancels csv'!$B:$B,'Branch View'!$B12,'IM Cancels csv'!$D:$D,'Branch View'!$I$1) -> 38957.91 | H12: =D12/F12 -> 1.0508475 | I12: =E12/G12 -> 1.1998087 | K12: =SUMIFS('All Sales csv'!$E:$E,'All Sales csv'!$A:$A,'Branch View'!$A12,'All Sales csv'!$B:$B,'Branch View'!$B12,'All Sales csv'!$D:$D,'Branch View'!$I$1) -> 101 | L12: =SUMIFS('All Sales csv'!$F:$F,'All Sales csv'!$A:$A,'Branch View'!$A12,'All Sales csv'!$B:$B,'Branch View'!$B12,'All Sales csv'!$D:$D,'Branch View'!$I$1) -> 82877.68 | M12: =SUMIFS('Cancels csv'!E:E,'Cancels csv'!A:A,'Branch View'!A12,'Cancels csv'!B:B,'Branch View'!B12,'Cancels csv'!D:D,'Branch View'!$I$1) -> 267 | N12: =SUMIFS('Cancels csv'!F:F,'Cancels csv'!A:A,'Branch View'!A12,'Cancels csv'!B:B,'Branch View'!B12,'Cancels csv'!D:D,'Branch View'!$I$1) -> 201852.22 | O12: =K12/M12 -> 0.37827715 | P12: =L12/N12 -> 0.41058592
A13: 2022 | B13: 11 | C13: November | D13: =SUMIFS('Sales csv'!E:E,'Sales csv'!A:A,'Branch View'!A13,'Sales csv'!B:B,'Branch View'!B13,'Sales csv'!D:D,'Branch View'!$I$1) -> 36 | E13: =SUMIFS('Sales csv'!F:F,'Sales csv'!A:A,'Branch View'!A13,'Sales csv'!B:B,'Branch View'!B13,'Sales csv'!D:D,'Branch View'!$I$1) -> 32816.66 | F13: =SUMIFS('IM Cancels csv'!$E:$E,'IM Cancels csv'!$A:$A,'Branch View'!$A13,'IM Cancels csv'!$B:$B,'Branch View'!$B13,'IM Cancels csv'!$D:$D,'Branch View'!$I$1) -> 18 | G13: =SUMIFS('IM Cancels csv'!$F:$F,'IM Cancels csv'!$A:$A,'Branch View'!$A13,'IM Cancels csv'!$B:$B,'Branch View'!$B13,'IM Cancels csv'!$D:$D,'Branch View'!$I$1) -> 14993.22 | H13: =D13/F13 -> 2 | I13: =E13/G13 -> 2.1887667 | K13: =SUMIFS('All Sales csv'!$E:$E,'All Sales csv'!$A:$A,'Branch View'!$A13,'All Sales csv'!$B:$B,'Branch View'!$B13,'All Sales csv'!$D:$D,'Branch View'!$I$1) -> 46 | L13: =SUMIFS('All Sales csv'!$F:$F,'All Sales csv'!$A:$A,'Branch View'!$A13,'All Sales csv'!$B:$B,'Branch View'!$B13,'All Sales csv'!$D:$D,'Branch View'!$I$1) -> 40985.05 | M13: =SUMIFS('Cancels csv'!E:E,'Cancels csv'!A:A,'Branch View'!A13,'Cancels csv'!B:B,'Branch View'!B13,'Cancels csv'!D:D,'Branch View'!$I$1) -> 133 | N13: =SUMIFS('Cancels csv'!F:F,'Cancels csv'!A:A,'Branch View'!A13,'Cancels csv'!B:B,'Branch View'!B13,'Cancels csv'!D:D,'Branch View'!$I$1) -> 113995.35 | O13: =K13/M13 -> 0.34586466 | P13: =L13/N13 -> 0.35953265
A14: 2022 | B14: 12 | C14: December | D14: =SUMIFS('Sales csv'!E:E,'Sales csv'!A:A,'Branch View'!A14,'Sales csv'!B:B,'Branch View'!B14,'Sales csv'!D:D,'Branch View'!$I$1) -> 12 | E14: =SUMIFS('Sales csv'!F:F,'Sales csv'!A:A,'Branch View'!A14,'Sales csv'!B:B,'Branch View'!B14,'Sales csv'!D:D,'Branch View'!$I$1) -> 10769.82 | F14: =SUMIFS('IM Cancels csv'!$E:$E,'IM Cancels csv'!$A:$A,'Branch View'!$A14,'IM Cancels csv'!$B:$B,'Branch View'!$B14,'IM Cancels csv'!$D:$D,'Branch View'!$I$1) -> 107 | G14: =SUMIFS('IM Cancels csv'!$F:$F,'IM Cancels csv'!$A:$A,'Branch View'!$A14,'IM Cancels csv'!$B:$B,'Branch View'!$B14,'IM Cancels csv'!$D:$D,'Branch View'!$I$1) -> 41090.51 | H14: =D14/F14 -> 0.11214953 | I14: =E14/G14 -> 0.26209993 | K14: =SUMIFS('All Sales csv'!$E:$E,'All Sales csv'!$A:$A,'Branch View'!$A14,'All Sales csv'!$B:$B,'Branch View'!$B14,'All Sales csv'!$D:$D,'Branch View'!$I$1) -> 26 | L14: =SUMIFS('All Sales csv'!$F:$F,'All Sales csv'!$A:$A,'Branch View'!$A14,'All Sales csv'!$B:$B,'Branch View'!$B14,'All Sales csv'!$D:$D,'Branch View'!$I$1) -> 22594.79 | M14: =SUMIFS('Cancels csv'!E:E,'Cancels csv'!A:A,'Branch View'!A14,'Cancels csv'!B:B,'Branch View'!B14,'Cancels csv'!D:D,'Branch View'!$I$1) -> 232 | N14: =SUMIFS('Cancels csv'!F:F,'Cancels csv'!A:A,'Branch View'!A14,'Cancels csv'!B:B,'Branch View'!B14,'Cancels csv'!D:D,'Branch View'!$I$1) -> 134580.71 | O14: =K14/M14 -> 0.11206897 | P14: =L14/N14 -> 0.16789026
A15: 2022 | B15: Totals | D15: =SUM(D3:D14) -> 571 | E15: =SUM(E3:E14) -> 418888.36 | F15: =SUM(F3:F14) -> 441 | G15: =SUM(G3:G14) -> 262361.75 | H15: =D15/F15 -> 1.2947846 | I15: =E15/G15 -> 1.5966061 | K15: =SUM(K3:K14) -> 2209 | L15: =SUM(L3:L14) -> 1947041.8 | M15: =SUM(M3:M14) -> 2235 | N15: =SUM(N3:N14) -> 1617677.1 | O15: =K15/M15 -> 0.98836689 | P15: =L15/N15 -> 1.2036035
A16: 2023 | B16: 1 | C16: January | D16: =SUMIFS('Sales csv'!$E:$E,'Sales csv'!$A:$A,'Branch View'!$A16,'Sales csv'!$B:$B,'Branch View'!$B16,'Sales csv'!$D:$D,'Branch View'!$I$1) -> 12 | E16: =SUMIFS('Sales csv'!$F:$F,'Sales csv'!$A:$A,'Branch View'!$A16,'Sales csv'!$B:$B,'Branch View'!$B16,'Sales csv'!$D:$D,'Branch View'!$I$1) -> 11583.78 | F16: =SUMIFS('IM Cancels csv'!$E:$E,'IM Cancels csv'!$A:$A,'Branch View'!$A16,'IM Cancels csv'!$B:$B,'Branch View'!$B16,'IM Cancels csv'!$D:$D,'Branch View'!$I$1) -> 31 | G16: =SUMIFS('IM Cancels csv'!$F:$F,'IM Cancels csv'!$A:$A,'Branch View'!$A16,'IM Cancels csv'!$B:$B,'Branch View'!$B16,'IM Cancels csv'!$D:$D,'Branch View'!$I$1) -> 22432.26 | H16: =D16/F16 -> 0.38709677 | I16: =E16/G16 -> 0.51638934 | K16: =SUMIFS('All Sales csv'!$E:$E,'All Sales csv'!$A:$A,'Branch View'!$A16,'All Sales csv'!$B:$B,'Branch View'!$B16,'All Sales csv'!$D:$D,'Branch View'!$I$1) -> 27 | L16: =SUMIFS('All Sales csv'!$F:$F,'All Sales csv'!$A:$A,'Branch View'!$A16,'All Sales csv'!$B:$B,'Branch View'!$B16,'All Sales csv'!$D:$D,'Branch View'!$I$1) -> 24470.38 | M16: =SUMIFS('Cancels csv'!E:E,'Cancels csv'!A:A,'Branch View'!A16,'Cancels csv'!B:B,'Branch View'!B16,'Cancels csv'!D:D,'Branch View'!$I$1) -> 204 | N16: =SUMIFS('Cancels csv'!F:F,'Cancels csv'!A:A,'Branch View'!A16,'Cancels csv'!B:B,'Branch View'!B16,'Cancels csv'!D:D,'Branch View'!$I$1) -> 161563.26 | O16: =K16/M16 -> 0.13235294 | P16: =L16/N16 -> 0.15146005
A17: 2023 | B17: 2 | C17: February | D17: =SUMIFS('Sales csv'!E:E,'Sales csv'!A:A,'Branch View'!A17,'Sales csv'!B:B,'Branch View'!B17,'Sales csv'!D:D,'Branch View'!$I$1) -> 13 | E17: =SUMIFS('Sales csv'!F:F,'Sales csv'!A:A,'Branch View'!A17,'Sales csv'!B:B,'Branch View'!B17,'Sales csv'!D:D,'Branch View'!$I$1) -> 12924.48 | F17: =SUMIFS('IM Cancels csv'!$E:$E,'IM Cancels csv'!$A:$A,'Branch View'!$A17,'IM Cancels csv'!$B:$B,'Branch View'!$B17,'IM Cancels csv'!$D:$D,'Branch View'!$I$1) -> 14 | G17: =SUMIFS('IM Cancels csv'!$F:$F,'IM Cancels csv'!$A:$A,'Branch View'!$A17,'IM Cancels csv'!$B:$B,'Branch View'!$B17,'IM Cancels csv'!$D:$D,'Branch View'!$I$1) -> 11818.86 | H17: =D17/F17 -> 0.92857143 | I17: =E17/G17 -> 1.0935471 | K17: =SUMIFS('All Sales csv'!$E:$E,'All Sales csv'!$A:$A,'Branch View'!$A17,'All Sales csv'!$B:$B,'Branch View'!$B17,'All Sales csv'!$D:$D,'Branch View'!$I$1) -> 23 | L17: =SUMIFS('All Sales csv'!$F:$F,'All Sales csv'!$A:$A,'Branch View'!$A17,'All Sales csv'!$B:$B,'Branch View'!$B17,'All Sales csv'!$D:$D,'Branch View'!$I$1) -> 20845.78 | M17: =SUMIFS('Cancels csv'!E:E,'Cancels csv'!A:A,'Branch View'!A17,'Cancels csv'!B:B,'Branch View'!B17,'Cancels csv'!D:D,'Branch View'!$I$1) -> 121 | N17: =SUMIFS('Cancels csv'!F:F,'Cancels csv'!A:A,'Branch View'!A17,'Cancels csv'!B:B,'Branch View'!B17,'Cancels csv'!D:D,'Branch View'!$I$1) -> 105084.75 | O17: =K17/M17 -> 0.19008264 | P17: =L17/N17 -> 0.19837112
A18: 2023 | B18: 3 | C18: March | D18: =SUMIFS('Sales csv'!E:E,'Sales csv'!A:A,'Branch View'!A18,'Sales csv'!B:B,'Branch View'!B18,'Sales csv'!D:D,'Branch View'!$I$1) -> 19 | E18: =SUMIFS('Sales csv'!F:F,'Sales csv'!A:A,'Branch View'!A18,'Sales csv'!B:B,'Branch View'!B18,'Sales csv'!D:D,'Branch View'!$I$1) -> 16800.37 | F18: =SUMIFS('IM Cancels csv'!$E:$E,'IM Cancels csv'!$A:$A,'Branch View'!$A18,'IM Cancels csv'!$B:$B,'Branch View'!$B18,'IM Cancels csv'!$D:$D,'Branch View'!$I$1) -> 24 | G18: =SUMIFS('IM Cancels csv'!$F:$F,'IM Cancels csv'!$A:$A,'Branch View'!$A18,'IM Cancels csv'!$B:$B,'Branch View'!$B18,'IM Cancels csv'!$D:$D,'Branch View'!$I$1) -> 19782.26 | H18: =D18/F18 -> 0.79166667 | I18: =E18/G18 -> 0.84926444 | K18: =SUMIFS('All Sales csv'!$E:$E,'All Sales csv'!$A:$A,'Branch View'!$A18,'All Sales csv'!$B:$B,'Branch View'!$B18,'All Sales csv'!$D:$D,'Branch View'!$I$1) -> 40 | L18: =SUMIFS('All Sales csv'!$F:$F,'All Sales csv'!$A:$A,'Branch View'!$A18,'All Sales csv'!$B:$B,'Branch View'!$B18,'All Sales csv'!$D:$D,'Branch View'!$I$1) -> 34927.28 | M18: =SUMIFS('Cancels csv'!E:E,'Cancels csv'!A:A,'Branch View'!A18,'Cancels csv'!B:B,'Branch View'!B18,'Cancels csv'!D:D,'Branch View'!$I$1) -> 121 | N18: =SUMIFS('Cancels csv'!F:F,'Cancels csv'!A:A,'Branch View'!A18,'Cancels csv'!B:B,'Branch View'!B18,'Cancels csv'!D:D,'Branch View'!$I$1) -> 99546.25 | O18: =K18/M18 -> 0.33057851 | P18: =L18/N18 -> 0.35086485
A19: 2023 | B19: 4 | C19: April | D19: =SUMIFS('Sales csv'!E:E,'Sales csv'!A:A,'Branch View'!A19,'Sales csv'!B:B,'Branch View'!B19,'Sales csv'!D:D,'Branch View'!$I$1) -> 47 | E19: =SUMIFS('Sales csv'!F:F,'Sales csv'!A:A,'Branch View'!A19,'Sales csv'!B:B,'Branch View'!B19,'Sales csv'!D:D,'Branch View'!$I$1) -> 42376.2 | F19: =SUMIFS('IM Cancels csv'!$E:$E,'IM Cancels csv'!$A:$A,'Branch View'!$A19,'IM Cancels csv'!$B:$B,'Branch View'!$B19,'IM Cancels csv'!$D:$D,'Branch View'!$I$1) -> 21 | G19: =SUMIFS('IM Cancels csv'!$F:$F,'IM Cancels csv'!$A:$A,'Branch View'!$A19,'IM Cancels csv'!$B:$B,'Branch View'!$B19,'IM Cancels csv'!$D:$D,'Branch View'!$I$1) -> 19161.15 | H19: =D19/F19 -> 2.2380952 | I19: =E19/G19 -> 2.2115687 | K19: =SUMIFS('All Sales csv'!$E:$E,'All Sales csv'!$A:$A,'Branch View'!$A19,'All Sales csv'!$B:$B,'Branch View'!$B19,'All Sales csv'!$D:$D,'Branch View'!$I$1) -> 120 | L19: =SUMIFS('All Sales csv'!$F:$F,'All Sales csv'!$A:$A,'Branch View'!$A19,'All Sales csv'!$B:$B,'Branch View'!$B19,'All Sales csv'!$D:$D,'Branch View'!$I$1) -> 108108.63 | M19: =SUMIFS('Cancels csv'!E:E,'Cancels csv'!A:A,'Branch View'!A19,'Cancels csv'!B:B,'Branch View'!B19,'Cancels csv'!D:D,'Branch View'!$I$1) -> 104 | N19: =SUMIFS('Cancels csv'!F:F,'Cancels csv'!A:A,'Branch View'!A19,'Cancels csv'!B:B,'Branch View'!B19,'Cancels csv'!D:D,'Branch View'!$I$1) -> 89323.22 | O19: =K19/M19 -> 1.1538462 | P19: =L19/N19 -> 1.2103082
A20: 2023 | B20: 5 | C20: May | D20: =SUMIFS('Sales csv'!E:E,'Sales csv'!A:A,'Branch View'!A20,'Sales csv'!B:B,'Branch View'!B20,'Sales csv'!D:D,'Branch View'!$I$1) -> 55 | E20: =SUMIFS('Sales csv'!F:F,'Sales csv'!A:A,'Branch View'!A20,'Sales csv'!B:B,'Branch View'!B20,'Sales csv'!D:D,'Branch View'!$I$1) -> 48798.21 | F20: =SUMIFS('IM Cancels csv'!$E:$E,'IM Cancels csv'!$A:$A,'Branch View'!$A20,'IM Cancels csv'!$B:$B,'Branch View'!$B20,'IM Cancels csv'!$D:$D,'Branch View'!$I$1) -> 20 | G20: =SUMIFS('IM Cancels csv'!$F:$F,'IM Cancels csv'!$A:$A,'Branch View'!$A20,'IM Cancels csv'!$B:$B,'Branch View'!$B20,'IM Cancels csv'!$D:$D,'Branch View'!$I$1) -> 13948.1 | H20: =D20/F20 -> 2.75 | I20: =E20/G20 -> 3.4985561 | K20: =SUMIFS('All Sales csv'!$E:$E,'All Sales csv'!$A:$A,'Branch View'!$A20,'All Sales csv'!$B:$B,'Branch View'!$B20,'All Sales csv'!$D:$D,'Branch View'!$I$1) -> 627 | L20: =SUMIFS('All Sales csv'!$F:$F,'All Sales csv'!$A:$A,'Branch View'!$A20,'All Sales csv'!$B:$B,'Branch View'!$B20,'All Sales csv'!$D:$D,'Branch View'!$I$1) -> 588069.29 | M20: =SUMIFS('Cancels csv'!E:E,'Cancels csv'!A:A,'Branch View'!A20,'Cancels csv'!B:B,'Branch View'!B20,'Cancels csv'!D:D,'Branch View'!$I$1) -> 145 | N20: =SUMIFS('Cancels csv'!F:F,'Cancels csv'!A:A,'Branch View'!A20,'Cancels csv'!B:B,'Branch View'!B20,'Cancels csv'!D:D,'Branch View'!$I$1) -> 123194.06 | O20: =K20/M20 -> 4.3241379 | P20: =L20/N20 -> 4.7735198
A21: 2023 | B21: 6 | C21: June | D21: =SUMIFS('Sales csv'!E:E,'Sales csv'!A:A,'Branch View'!A21,'Sales csv'!B:B,'Branch View'!B21,'Sales csv'!D:D,'Branch View'!$I$1) -> 35 | E21: =SUMIFS('Sales csv'!F:F,'Sales csv'!A:A,'Branch View'!A21,'Sales csv'!B:B,'Branch View'!B21,'Sales csv'!D:D,'Branch View'!$I$1) -> 30859.12 | F21: =SUMIFS('IM Cancels csv'!$E:$E,'IM Cancels csv'!$A:$A,'Branch View'!$A21,'IM Cancels csv'!$B:$B,'Branch View'!$B21,'IM Cancels csv'!$D:$D,'Branch View'!$I$1) -> 35 | G21: =SUMIFS('IM Cancels csv'!$F:$F,'IM Cancels csv'!$A:$A,'Branch View'!$A21,'IM Cancels csv'!$B:$B,'Branch View'!$B21,'IM Cancels csv'!$D:$D,'Branch View'!$I$1) -> 30252.12 | H21: =D21/F21 -> 1 | I21: =E21/G21 -> 1.0200647 | K21: =SUMIFS('All Sales csv'!$E:$E,'All Sales csv'!$A:$A,'Branch View'!$A21,'All Sales csv'!$B:$B,'Branch View'!$B21,'All Sales csv'!$D:$D,'Branch View'!$I$1) -> 796 | L21: =SUMIFS('All Sales csv'!$F:$F,'All Sales csv'!$A:$A,'Branch View'!$A21,'All Sales csv'!$B:$B,'Branch View'!$B21,'All Sales csv'!$D:$D,'Branch View'!$I$1) -> 754994.03 | M21: =SUMIFS('Cancels csv'!E:E,'Cancels csv'!A:A,'Branch View'!A21,'Cancels csv'!B:B,'Branch View'!B21,'Cancels csv'!D:D,'Branch View'!$I$1) -> 278 | N21: =SUMIFS('Cancels csv'!F:F,'Cancels csv'!A:A,'Branch View'!A21,'Cancels csv'!B:B,'Branch View'!B21,'Cancels csv'!D:D,'Branch View'!$I$1) -> 218856.63 | O21: =K21/M21 -> 2.8633094 | P21: =L21/N21 -> 3.4497197
A22: 2023 | B22: 7 | C22: July | D22: =SUMIFS('Sales csv'!E:E,'Sales csv'!A:A,'Branch View'!A22,'Sales csv'!B:B,'Branch View'!B22,'Sales csv'!D:D,'Branch View'!$I$1) -> 117 | E22: =SUMIFS('Sales csv'!F:F,'Sales csv'!A:A,'Branch View'!A22,'Sales csv'!B:B,'Branch View'!B22,'Sales csv'!D:D,'Branch View'!$I$1) -> 76260.85 | F22: =SUMIFS('IM Cancels csv'!$E:$E,'IM Cancels csv'!$A:$A,'Branch View'!$A22,'IM Cancels csv'!$B:$B,'Branch View'!$B22,'IM Cancels csv'!$D:$D,'Branch View'!$I$1) -> 20 | G22: =SUMIFS('IM Cancels csv'!$F:$F,'IM Cancels csv'!$A:$A,'Branch View'!$A22,'IM Cancels csv'!$B:$B,'Branch View'!$B22,'IM Cancels csv'!$D:$D,'Branch View'!$I$1) -> 16124.9 | H22: =D22/F22 -> 5.85 | I22: =E22/G22 -> 4.7293844 | K22: =SUMIFS('All Sales csv'!$E:$E,'All Sales csv'!$A:$A,'Branch View'!$A22,'All Sales csv'!$B:$B,'Branch View'!$B22,'All Sales csv'!$D:$D,'Branch View'!$I$1) -> 765 | L22: =SUMIFS('All Sales csv'!$F:$F,'All Sales csv'!$A:$A,'Branch View'!$A22,'All Sales csv'!$B:$B,'Branch View'!$B22,'All Sales csv'!$D:$D,'Branch View'!$I$1) -> 695755.11 | M22: =SUMIFS('Cancels csv'!E:E,'Cancels csv'!A:A,'Branch View'!A22,'Cancels csv'!B:B,'Branch View'!B22,'Cancels csv'!D:D,'Branch View'!$I$1) -> 214 | N22: =SUMIFS('Cancels csv'!F:F,'Cancels csv'!A:A,'Branch View'!A22,'Cancels csv'!B:B,'Branch View'!B22,'Cancels csv'!D:D,'Branch View'!$I$1) -> 187071.08 | O22: =K22/M22 -> 3.5747664 | P22: =L22/N22 -> 3.7192019
A23: 2023 | B23: 8 | C23: August | D23: =SUMIFS('Sales csv'!E:E,'Sales csv'!A:A,'Branch View'!A23,'Sales csv'!B:B,'Branch View'!B23,'Sales csv'!D:D,'Branch View'!$I$1) -> 162 | E23: =SUMIFS('Sales csv'!F:F,'Sales csv'!A:A,'Branch View'!A23,'Sales csv'!B:B,'Branch View'!B23,'Sales csv'!D:D,'Branch View'!$I$1) -> 121124.34 | F23: =SUMIFS('IM Cancels csv'!$E:$E,'IM Cancels csv'!$A:$A,'Branch View'!$A23,'IM Cancels csv'!$B:$B,'Branch View'!$B23,'IM Cancels csv'!$D:$D,'Branch View'!$I$1) -> 57 | G23: =SUMIFS('IM Cancels csv'!$F:$F,'IM Cancels csv'!$A:$A,'Branch View'!$A23,'IM Cancels csv'!$B:$B,'Branch View'!$B23,'IM Cancels csv'!$D:$D,'Branch View'!$I$1) -> 32495.2 | H23: =D23/F23 -> 2.8421053 | I23: =E23/G23 -> 3.7274533 | K23: =SUMIFS('All Sales csv'!$E:$E,'All Sales csv'!$A:$A,'Branch View'!$A23,'All Sales csv'!$B:$B,'Branch View'!$B23,'All Sales csv'!$D:$D,'Branch View'!$I$1) -> 506 | L23: =SUMIFS('All Sales csv'!$F:$F,'All Sales csv'!$A:$A,'Branch View'!$A23,'All Sales csv'!$B:$B,'Branch View'!$B23,'All Sales csv'!$D:$D,'Branch View'!$I$1) -> 439398.81 | M23: =SUMIFS('Cancels csv'!E:E,'Cancels csv'!A:A,'Branch View'!A23,'Cancels csv'!B:B,'Branch View'!B23,'Cancels csv'!D:D,'Branch View'!$I$1) -> 261 | N23: =SUMIFS('Cancels csv'!F:F,'Cancels csv'!A:A,'Branch View'!A23,'Cancels csv'!B:B,'Branch View'!B23,'Cancels csv'!D:D,'Branch View'!$I$1) -> 205313.52 | O23: =K23/M23 -> 1.9386973 | P23: =L23/N23 -> 2.1401358
A24: 2023 | B24: 9 | C24: September | D24: =SUMIFS('Sales csv'!E:E,'Sales csv'!A:A,'Branch View'!A24,'Sales csv'!B:B,'Branch View'!B24,'Sales csv'!D:D,'Branch View'!$I$1) -> 80 | E24: =SUMIFS('Sales csv'!F:F,'Sales csv'!A:A,'Branch View'!A24,'Sales csv'!B:B,'Branch View'!B24,'Sales csv'!D:D,'Branch View'!$I$1) -> 66347.29 | F24: =SUMIFS('IM Cancels csv'!$E:$E,'IM Cancels csv'!$A:$A,'Branch View'!$A24,'IM Cancels csv'!$B:$B,'Branch View'!$B24,'IM Cancels csv'!$D:$D,'Branch View'!$I$1) -> 80 | G24: =SUMIFS('IM Cancels csv'!$F:$F,'IM Cancels csv'!$A:$A,'Branch View'!$A24,'IM Cancels csv'!$B:$B,'Branch View'!$B24,'IM Cancels csv'!$D:$D,'Branch View'!$I$1) -> 44116.39 | H24: =D24/F24 -> 1 | I24: =E24/G24 -> 1.5039148 | K24: =SUMIFS('All Sales csv'!$E:$E,'All Sales csv'!$A:$A,'Branch View'!$A24,'All Sales csv'!$B:$B,'Branch View'!$B24,'All Sales csv'!$D:$D,'Branch View'!$I$1) -> 155 | L24: =SUMIFS('All Sales csv'!$F:$F,'All Sales csv'!$A:$A,'Branch View'!$A24,'All Sales csv'!$B:$B,'Branch View'!$B24,'All Sales csv'!$D:$D,'Branch View'!$I$1) -> 132482.49 | M24: =SUMIFS('Cancels csv'!E:E,'Cancels csv'!A:A,'Branch View'!A24,'Cancels csv'!B:B,'Branch View'!B24,'Cancels csv'!D:D,'Branch View'!$I$1) -> 268 | N24: =SUMIFS('Cancels csv'!F:F,'Cancels csv'!A:A,'Branch View'!A24,'Cancels csv'!B:B,'Branch View'!B24,'Cancels csv'!D:D,'Branch View'!$I$1) -> 208342.45 | O24: =K24/M24 -> 0.57835821 | P24: =L24/N24 -> 0.63588813
A25: 2023 | B25: 10 | C25: October | D25: =SUMIFS('Sales csv'!E:E,'Sales csv'!A:A,'Branch View'!A25,'Sales csv'!B:B,'Branch View'!B25,'Sales csv'!D:D,'Branch View'!$I$1) -> 40 | E25: =SUMIFS('Sales csv'!F:F,'Sales csv'!A:A,'Branch View'!A25,'Sales csv'!B:B,'Branch View'!B25,'Sales csv'!D:D,'Branch View'!$I$1) -> 34596.05 | F25: =SUMIFS('IM Cancels csv'!$E:$E,'IM Cancels csv'!$A:$A,'Branch View'!$A25,'IM Cancels csv'!$B:$B,'Branch View'!$B25,'IM Cancels csv'!$D:$D,'Branch View'!$I$1) -> 41 | G25: =SUMIFS('IM Cancels csv'!$F:$F,'IM Cancels csv'!$A:$A,'Branch View'!$A25,'IM Cancels csv'!$B:$B,'Branch View'!$B25,'IM Cancels csv'!$D:$D,'Branch View'!$I$1) -> 32006.96 | H25: =D25/F25 -> 0.97560976 | I25: =E25/G25 -> 1.0808915 | K25: =SUMIFS('All Sales csv'!$E:$E,'All Sales csv'!$A:$A,'Branch View'!$A25,'All Sales csv'!$B:$B,'Branch View'!$B25,'All Sales csv'!$D:$D,'Branch View'!$I$1) -> 81 | L25: =SUMIFS('All Sales csv'!$F:$F,'All Sales csv'!$A:$A,'Branch View'!$A25,'All Sales csv'!$B:$B,'Branch View'!$B25,'All Sales csv'!$D:$D,'Branch View'!$I$1) -> 77463.13 | M25: =SUMIFS('Cancels csv'!E:E,'Cancels csv'!A:A,'Branch View'!A25,'Cancels csv'!B:B,'Branch View'!B25,'Cancels csv'!D:D,'Branch View'!$I$1) -> 188 | N25: =SUMIFS('Cancels csv'!F:F,'Cancels csv'!A:A,'Branch View'!A25,'Cancels csv'!B:B,'Branch View'!B25,'Cancels csv'!D:D,'Branch View'!$I$1) -> 167581.38 | O25: =K25/M25 -> 0.43085106 | P25: =L25/N25 -> 0.46224187
A26: 2023 | B26: 11 | C26: November | D26: =SUMIFS('Sales csv'!E:E,'Sales csv'!A:A,'Branch View'!A26,'Sales csv'!B:B,'Branch View'!B26,'Sales csv'!D:D,'Branch View'!$I$1) -> 17 | E26: =SUMIFS('Sales csv'!F:F,'Sales csv'!A:A,'Branch View'!A26,'Sales csv'!B:B,'Branch View'!B26,'Sales csv'!D:D,'Branch View'!$I$1) -> 16476.99 | F26: =SUMIFS('IM Cancels csv'!$E:$E,'IM Cancels csv'!$A:$A,'Branch View'!$A26,'IM Cancels csv'!$B:$B,'Branch View'!$B26,'IM Cancels csv'!$D:$D,'Branch View'!$I$1) -> 47 | G26: =SUMIFS('IM Cancels csv'!$F:$F,'IM Cancels csv'!$A:$A,'Branch View'!$A26,'IM Cancels csv'!$B:$B,'Branch View'!$B26,'IM Cancels csv'!$D:$D,'Branch View'!$I$1) -> 37291.33 | H26: =D26/F26 -> 0.36170213 | I26: =E26/G26 -> 0.44184506 | K26: =SUMIFS('All Sales csv'!$E:$E,'All Sales csv'!$A:$A,'Branch View'!$A26,'All Sales csv'!$B:$B,'Branch View'!$B26,'All Sales csv'!$D:$D,'Branch View'!$I$1) -> 37 | L26: =SUMIFS('All Sales csv'!$F:$F,'All Sales csv'!$A:$A,'Branch View'!$A26,'All Sales csv'!$B:$B,'Branch View'!$B26,'All Sales csv'!$D:$D,'Branch View'!$I$1) -> 35340.18 | M26: =SUMIFS('Cancels csv'!E:E,'Cancels csv'!A:A,'Branch View'!A26,'Cancels csv'!B:B,'Branch View'!B26,'Cancels csv'!D:D,'Branch View'!$I$1) -> 204 | N26: =SUMIFS('Cancels csv'!F:F,'Cancels csv'!A:A,'Branch View'!A26,'Cancels csv'!B:B,'Branch View'!B26,'Cancels csv'!D:D,'Branch View'!$I$1) -> 177686.28 | O26: =K26/M26 -> 0.18137255 | P26: =L26/N26 -> 0.19889088
A27: 2023 | B27: 12 | C27: December | D27: =SUMIFS('Sales csv'!E:E,'Sales csv'!A:A,'Branch View'!A27,'Sales csv'!B:B,'Branch View'!B27,'Sales csv'!D:D,'Branch View'!$I$1) -> 23 | E27: =SUMIFS('Sales csv'!F:F,'Sales csv'!A:A,'Branch View'!A27,'Sales csv'!B:B,'Branch View'!B27,'Sales csv'!D:D,'Branch View'!$I$1) -> 23640.38 | F27: =SUMIFS('IM Cancels csv'!$E:$E,'IM Cancels csv'!$A:$A,'Branch View'!$A27,'IM Cancels csv'!$B:$B,'Branch View'!$B27,'IM Cancels csv'!$D:$D,'Branch View'!$I$1) -> 29 | G27: =SUMIFS('IM Cancels csv'!$F:$F,'IM Cancels csv'!$A:$A,'Branch View'!$A27,'IM Cancels csv'!$B:$B,'Branch View'!$B27,'IM Cancels csv'!$D:$D,'Branch View'!$I$1) -> 26274.05 | H27: =D27/F27 -> 0.79310345 | I27: =E27/G27 -> 0.89976155 | K27: =SUMIFS('All Sales csv'!$E:$E,'All Sales csv'!$A:$A,'Branch View'!$A27,'All Sales csv'!$B:$B,'Branch View'!$B27,'All Sales csv'!$D:$D,'Branch View'!$I$1) -> 29 | L27: =SUMIFS('All Sales csv'!$F:$F,'All Sales csv'!$A:$A,'Branch View'!$A27,'All Sales csv'!$B:$B,'Branch View'!$B27,'All Sales csv'!$D:$D,'Branch View'!$I$1) -> 28509.61 | M27: =SUMIFS('Cancels csv'!E:E,'Cancels csv'!A:A,'Branch View'!A27,'Cancels csv'!B:B,'Branch View'!B27,'Cancels csv'!D:D,'Branch View'!$I$1) -> 163 | N27: =SUMIFS('Cancels csv'!F:F,'Cancels csv'!A:A,'Branch View'!A27,'Cancels csv'!B:B,'Branch View'!B27,'Cancels csv'!D:D,'Branch View'!$I$1) -> 148039.87 | O27: =K27/M27 -> 0.17791411 | P27: =L27/N27 -> 0.19258062
A28: 2023 | B28: Total | D28: =SUM(D16:D27) -> 620 | E28: =SUM(E16:E27) -> 501788.06 | F28: =SUM(F16:F27) -> 419 | G28: =SUM(G16:G27) -> 305703.58 | H28: =D28/F28 -> 1.4797136 | I28: =E28/G28 -> 1.6414203 | K28: =SUM(K16:K27) -> 3206 | L28: =SUM(L16:L27) -> 2940364.7 | M28: =SUM(M16:M27) -> 2271 | N28: =SUM(N16:N27) -> 1891602.8 | O28: =K28/M28 -> 1.4117129 | P28: =L28/N28 -> 1.5544303
A29: 2024 | B29: 1 | C29: January | D29: =SUMIFS('Sales csv'!$E:$E,'Sales csv'!$A:$A,'Branch View'!$A29,'Sales csv'!$B:$B,'Branch View'!$B29,'Sales csv'!$D:$D,'Branch View'!$I$1) -> 16 | E29: =SUMIFS('Sales csv'!$F:$F,'Sales csv'!$A:$A,'Branch View'!$A29,'Sales csv'!$B:$B,'Branch View'!$B29,'Sales csv'!$D:$D,'Branch View'!$I$1) -> 18632.26 | F29: =SUMIFS('IM Cancels csv'!$E:$E,'IM Cancels csv'!$A:$A,'Branch View'!$A29,'IM Cancels csv'!$B:$B,'Branch View'!$B29,'IM Cancels csv'!$D:$D,'Branch View'!$I$1) -> 45 | G29: =SUMIFS('IM Cancels csv'!$F:$F,'IM Cancels csv'!$A:$A,'Branch View'!$A29,'IM Cancels csv'!$B:$B,'Branch View'!$B29,'IM Cancels csv'!$D:$D,'Branch View'!$I$1) -> 29452.38 | H29: =D29/F29 -> 0.35555556 | I29: =E29/G29 -> 0.63262324 | K29: =SUMIFS('All Sales csv'!$E:$E,'All Sales csv'!$A:$A,'Branch View'!$A29,'All Sales csv'!$B:$B,'Branch View'!$B29,'All Sales csv'!$D:$D,'Branch View'!$I$1) -> 33 | L29: =SUMIFS('All Sales csv'!$F:$F,'All Sales csv'!$A:$A,'Branch View'!$A29,'All Sales csv'!$B:$B,'Branch View'!$B29,'All Sales csv'!$D:$D,'Branch View'!$I$1) -> 34512.97 | M29: =SUMIFS('Cancels csv'!E:E,'Cancels csv'!A:A,'Branch View'!A29,'Cancels csv'!B:B,'Branch View'!B29,'Cancels csv'!D:D,'Branch View'!$I$1) -> 208 | N29: =SUMIFS('Cancels csv'!F:F,'Cancels csv'!A:A,'Branch View'!A29,'Cancels csv'!B:B,'Branch View'!B29,'Cancels csv'!D:D,'Branch View'!$I$1) -> 179188.07 | O29: =K29/M29 -> 0.15865385 | P29: =L29/N29 -> 0.19260752
A30: 2024 | B30: 2 | C30: February | D30: =SUMIFS('Sales csv'!E:E,'Sales csv'!A:A,'Branch View'!A30,'Sales csv'!B:B,'Branch View'!B30,'Sales csv'!D:D,'Branch View'!$I$1) -> 19 | E30: =SUMIFS('Sales csv'!F:F,'Sales csv'!A:A,'Branch View'!A30,'Sales csv'!B:B,'Branch View'!B30,'Sales csv'!D:D,'Branch View'!$I$1) -> 18804.75 | F30: =SUMIFS('IM Cancels csv'!$E:$E,'IM Cancels csv'!$A:$A,'Branch View'!$A30,'IM Cancels csv'!$B:$B,'Branch View'!$B30,'IM Cancels csv'!$D:$D,'Branch View'!$I$1) -> 24 | G30: =SUMIFS('IM Cancels csv'!$F:$F,'IM Cancels csv'!$A:$A,'Branch View'!$A30,'IM Cancels csv'!$B:$B,'Branch View'!$B30,'IM Cancels csv'!$D:$D,'Branch View'!$I$1) -> 22051.49 | H30: =D30/F30 -> 0.79166667 | I30: =E30/G30 -> 0.8527655 | K30: =SUMIFS('All Sales csv'!$E:$E,'All Sales csv'!$A:$A,'Branch View'!$A30,'All Sales csv'!$B:$B,'Branch View'!$B30,'All Sales csv'!$D:$D,'Branch View'!$I$1) -> 48 | L30: =SUMIFS('All Sales csv'!$F:$F,'All Sales csv'!$A:$A,'Branch View'!$A30,'All Sales csv'!$B:$B,'Branch View'!$B30,'All Sales csv'!$D:$D,'Branch View'!$I$1) -> 42950.82 | M30: =SUMIFS('Cancels csv'!E:E,'Cancels csv'!A:A,'Branch View'!A30,'Cancels csv'!B:B,'Branch View'!B30,'Cancels csv'!D:D,'Branch View'!$I$1) -> 172 | N30: =SUMIFS('Cancels csv'!F:F,'Cancels csv'!A:A,'Branch View'!A30,'Cancels csv'!B:B,'Branch View'!B30,'Cancels csv'!D:D,'Branch View'!$I$1) -> 160652.68 | O30: =K30/M30 -> 0.27906977 | P30: =L30/N30 -> 0.26735203
A31: 2024 | B31: 3 | C31: March | D31: =SUMIFS('Sales csv'!E:E,'Sales csv'!A:A,'Branch View'!A31,'Sales csv'!B:B,'Branch View'!B31,'Sales csv'!D:D,'Branch View'!$I$1) -> 27 | E31: =SUMIFS('Sales csv'!F:F,'Sales csv'!A:A,'Branch View'!A31,'Sales csv'!B:B,'Branch View'!B31,'Sales csv'!D:D,'Branch View'!$I$1) -> 23697.14 | F31: =SUMIFS('IM Cancels csv'!$E:$E,'IM Cancels csv'!$A:$A,'Branch View'!$A31,'IM Cancels csv'!$B:$B,'Branch View'!$B31,'IM Cancels csv'!$D:$D,'Branch View'!$I$1) -> 24 | G31: =SUMIFS('IM Cancels csv'!$F:$F,'IM Cancels csv'!$A:$A,'Branch View'!$A31,'IM Cancels csv'!$B:$B,'Branch View'!$B31,'IM Cancels csv'!$D:$D,'Branch View'!$I$1) -> 21811.3 | H31: =D31/F31 -> 1.125 | I31: =E31/G31 -> 1.0864616 | K31: =SUMIFS('All Sales csv'!$E:$E,'All Sales csv'!$A:$A,'Branch View'!$A31,'All Sales csv'!$B:$B,'Branch View'!$B31,'All Sales csv'!$D:$D,'Branch View'!$I$1) -> 57 | L31: =SUMIFS('All Sales csv'!$F:$F,'All Sales csv'!$A:$A,'Branch View'!$A31,'All Sales csv'!$B:$B,'Branch View'!$B31,'All Sales csv'!$D:$D,'Branch View'!$I$1) -> 50516.99 | M31: =SUMIFS('Cancels csv'!E:E,'Cancels csv'!A:A,'Branch View'!A31,'Cancels csv'!B:B,'Branch View'!B31,'Cancels csv'!D:D,'Branch View'!$I$1) -> 138 | N31: =SUMIFS('Cancels csv'!F:F,'Cancels csv'!A:A,'Branch View'!A31,'Cancels csv'!B:B,'Branch View'!B31,'Cancels csv'!D:D,'Branch View'!$I$1) -> 121751.87 | O31: =K31/M31 -> 0.41304348 | P31: =L31/N31 -> 0.41491757
A32: 2024 | B32: 4 | C32: April | D32: =SUMIFS('Sales csv'!E:E,'Sales csv'!A:A,'Branch View'!A32,'Sales csv'!B:B,'Branch View'!B32,'Sales csv'!D:D,'Branch View'!$I$1) -> 48 | E32: =SUMIFS('Sales csv'!F:F,'Sales csv'!A:A,'Branch View'!A32,'Sales csv'!B:B,'Branch View'!B32,'Sales csv'!D:D,'Branch View'!$I$1) -> 45821.77 | F32: =SUMIFS('IM Cancels csv'!$E:$E,'IM Cancels csv'!$A:$A,'Branch View'!$A32,'IM Cancels csv'!$B:$B,'Branch View'!$B32,'IM Cancels csv'!$D:$D,'Branch View'!$I$1) -> 28 | G32: =SUMIFS('IM Cancels csv'!$F:$F,'IM Cancels csv'!$A:$A,'Branch View'!$A32,'IM Cancels csv'!$B:$B,'Branch View'!$B32,'IM Cancels csv'!$D:$D,'Branch View'!$I$1) -> 24057.8 | H32: =D32/F32 -> 1.7142857 | I32: =E32/G32 -> 1.9046534 | K32: =SUMIFS('All Sales csv'!$E:$E,'All Sales csv'!$A:$A,'Branch View'!$A32,'All Sales csv'!$B:$B,'Branch View'!$B32,'All Sales csv'!$D:$D,'Branch View'!$I$1) -> 203 | L32: =SUMIFS('All Sales csv'!$F:$F,'All Sales csv'!$A:$A,'Branch View'!$A32,'All Sales csv'!$B:$B,'Branch View'!$B32,'All Sales csv'!$D:$D,'Branch View'!$I$1) -> 183753.61 | M32: =SUMIFS('Cancels csv'!E:E,'Cancels csv'!A:A,'Branch View'!A32,'Cancels csv'!B:B,'Branch View'!B32,'Cancels csv'!D:D,'Branch View'!$I$1) -> 152 | N32: =SUMIFS('Cancels csv'!F:F,'Cancels csv'!A:A,'Branch View'!A32,'Cancels csv'!B:B,'Branch View'!B32,'Cancels csv'!D:D,'Branch View'!$I$1) -> 134877.83 | O32: =K32/M32 -> 1.3355263 | P32: =L32/N32 -> 1.3623707
A33: 2024 | B33: 5 | C33: May | D33: =SUMIFS('Sales csv'!E:E,'Sales csv'!A:A,'Branch View'!A33,'Sales csv'!B:B,'Branch View'!B33,'Sales csv'!D:D,'Branch View'!$I$1) -> 99 | E33: =SUMIFS('Sales csv'!F:F,'Sales csv'!A:A,'Branch View'!A33,'Sales csv'!B:B,'Branch View'!B33,'Sales csv'!D:D,'Branch View'!$I$1) -> 86878.18 | F33: =SUMIFS('IM Cancels csv'!$E:$E,'IM Cancels csv'!$A:$A,'Branch View'!$A33,'IM Cancels csv'!$B:$B,'Branch View'!$B33,'IM Cancels csv'!$D:$D,'Branch View'!$I$1) -> 32 | G33: =SUMIFS('IM Cancels csv'!$F:$F,'IM Cancels csv'!$A:$A,'Branch View'!$A33,'IM Cancels csv'!$B:$B,'Branch View'!$B33,'IM Cancels csv'!$D:$D,'Branch View'!$I$1) -> 29426.17 | H33: =D33/F33 -> 3.09375 | I33: =E33/G33 -> 2.9524121 | K33: =SUMIFS('All Sales csv'!$E:$E,'All Sales csv'!$A:$A,'Branch View'!$A33,'All Sales csv'!$B:$B,'Branch View'!$B33,'All Sales csv'!$D:$D,'Branch View'!$I$1) -> 935 | L33: =SUMIFS('All Sales csv'!$F:$F,'All Sales csv'!$A:$A,'Branch View'!$A33,'All Sales csv'!$B:$B,'Branch View'!$B33,'All Sales csv'!$D:$D,'Branch View'!$I$1) -> 842566.85 | M33: =SUMIFS('Cancels csv'!E:E,'Cancels csv'!A:A,'Branch View'!A33,'Cancels csv'!B:B,'Branch View'!B33,'Cancels csv'!D:D,'Branch View'!$I$1) -> 213 | N33: =SUMIFS('Cancels csv'!F:F,'Cancels csv'!A:A,'Branch View'!A33,'Cancels csv'!B:B,'Branch View'!B33,'Cancels csv'!D:D,'Branch View'!$I$1) -> 195057.6 | O33: =K33/M33 -> 4.3896714 | P33: =L33/N33 -> 4.3195797
A34: 2024 | B34: 6 | C34: June | D34: =SUMIFS('Sales csv'!E:E,'Sales csv'!A:A,'Branch View'!A34,'Sales csv'!B:B,'Branch View'!B34,'Sales csv'!D:D,'Branch View'!$I$1) -> 50 | E34: =SUMIFS('Sales csv'!F:F,'Sales csv'!A:A,'Branch View'!A34,'Sales csv'!B:B,'Branch View'!B34,'Sales csv'!D:D,'Branch View'!$I$1) -> 41813.27 | F34: =SUMIFS('IM Cancels csv'!$E:$E,'IM Cancels csv'!$A:$A,'Branch View'!$A34,'IM Cancels csv'!$B:$B,'Branch View'!$B34,'IM Cancels csv'!$D:$D,'Branch View'!$I$1) -> 28 | G34: =SUMIFS('IM Cancels csv'!$F:$F,'IM Cancels csv'!$A:$A,'Branch View'!$A34,'IM Cancels csv'!$B:$B,'Branch View'!$B34,'IM Cancels csv'!$D:$D,'Branch View'!$I$1) -> 20454.04 | H34: =D34/F34 -> 1.7857143 | I34: =E34/G34 -> 2.0442548 | K34: =SUMIFS('All Sales csv'!$E:$E,'All Sales csv'!$A:$A,'Branch View'!$A34,'All Sales csv'!$B:$B,'Branch View'!$B34,'All Sales csv'!$D:$D,'Branch View'!$I$1) -> 680 | L34: =SUMIFS('All Sales csv'!$F:$F,'All Sales csv'!$A:$A,'Branch View'!$A34,'All Sales csv'!$B:$B,'Branch View'!$B34,'All Sales csv'!$D:$D,'Branch View'!$I$1) -> 601848.17 | M34: =SUMIFS('Cancels csv'!E:E,'Cancels csv'!A:A,'Branch View'!A34,'Cancels csv'!B:B,'Branch View'!B34,'Cancels csv'!D:D,'Branch View'!$I$1) -> 251 | N34: =SUMIFS('Cancels csv'!F:F,'Cancels csv'!A:A,'Branch View'!A34,'Cancels csv'!B:B,'Branch View'!B34,'Cancels csv'!D:D,'Branch View'!$I$1) -> 218219.97 | O34: =K34/M34 -> 2.7091633 | P34: =L34/N34 -> 2.7579885
A35: 2024 | B35: 7 | C35: July | D35: =SUMIFS('Sales csv'!E:E,'Sales csv'!A:A,'Branch View'!A35,'Sales csv'!B:B,'Branch View'!B35,'Sales csv'!D:D,'Branch View'!$I$1) -> 102 | E35: =SUMIFS('Sales csv'!F:F,'Sales csv'!A:A,'Branch View'!A35,'Sales csv'!B:B,'Branch View'!B35,'Sales csv'!D:D,'Branch View'!$I$1) -> 86414.22 | F35: =SUMIFS('IM Cancels csv'!$E:$E,'IM Cancels csv'!$A:$A,'Branch View'!$A35,'IM Cancels csv'!$B:$B,'Branch View'!$B35,'IM Cancels csv'!$D:$D,'Branch View'!$I$1) -> 43 | G35: =SUMIFS('IM Cancels csv'!$F:$F,'IM Cancels csv'!$A:$A,'Branch View'!$A35,'IM Cancels csv'!$B:$B,'Branch View'!$B35,'IM Cancels csv'!$D:$D,'Branch View'!$I$1) -> 34992.97 | H35: =D35/F35 -> 2.372093 | I35: =E35/G35 -> 2.4694737 | K35: =SUMIFS('All Sales csv'!$E:$E,'All Sales csv'!$A:$A,'Branch View'!$A35,'All Sales csv'!$B:$B,'Branch View'!$B35,'All Sales csv'!$D:$D,'Branch View'!$I$1) -> 693 | L35: =SUMIFS('All Sales csv'!$F:$F,'All Sales csv'!$A:$A,'Branch View'!$A35,'All Sales csv'!$B:$B,'Branch View'!$B35,'All Sales csv'!$D:$D,'Branch View'!$I$1) -> 595685.7 | M35: =SUMIFS('Cancels csv'!E:E,'Cancels csv'!A:A,'Branch View'!A35,'Cancels csv'!B:B,'Branch View'!B35,'Cancels csv'!D:D,'Branch View'!$I$1) -> 296 | N35: =SUMIFS('Cancels csv'!F:F,'Cancels csv'!A:A,'Branch View'!A35,'Cancels csv'!B:B,'Branch View'!B35,'Cancels csv'!D:D,'Branch View'!$I$1) -> 256293.66 | O35: =K35/M35 -> 2.3412162 | P35: =L35/N35 -> 2.3242311
A36: 2024 | B36: 8 | C36: August | D36: =SUMIFS('Sales csv'!E:E,'Sales csv'!A:A,'Branch View'!A36,'Sales csv'!B:B,'Branch View'!B36,'Sales csv'!D:D,'Branch View'!$I$1) -> 96 | E36: =SUMIFS('Sales csv'!F:F,'Sales csv'!A:A,'Branch View'!A36,'Sales csv'!B:B,'Branch View'!B36,'Sales csv'!D:D,'Branch View'!$I$1) -> 75894.73 | F36: =SUMIFS('IM Cancels csv'!$E:$E,'IM Cancels csv'!$A:$A,'Branch View'!$A36,'IM Cancels csv'!$B:$B,'Branch View'!$B36,'IM Cancels csv'!$D:$D,'Branch View'!$I$1) -> 54 | G36: =SUMIFS('IM Cancels csv'!$F:$F,'IM Cancels csv'!$A:$A,'Branch View'!$A36,'IM Cancels csv'!$B:$B,'Branch View'!$B36,'IM Cancels csv'!$D:$D,'Branch View'!$I$1) -> 39237.45 | H36: =D36/F36 -> 1.7777778 | I36: =E36/G36 -> 1.9342422 | K36: =SUMIFS('All Sales csv'!$E:$E,'All Sales csv'!$A:$A,'Branch View'!$A36,'All Sales csv'!$B:$B,'Branch View'!$B36,'All Sales csv'!$D:$D,'Branch View'!$I$1) -> 478 | L36: =SUMIFS('All Sales csv'!$F:$F,'All Sales csv'!$A:$A,'Branch View'!$A36,'All Sales csv'!$B:$B,'Branch View'!$B36,'All Sales csv'!$D:$D,'Branch View'!$I$1) -> 395109.88 | M36: =SUMIFS('Cancels csv'!E:E,'Cancels csv'!A:A,'Branch View'!A36,'Cancels csv'!B:B,'Branch View'!B36,'Cancels csv'!D:D,'Branch View'!$I$1) -> 307 | N36: =SUMIFS('Cancels csv'!F:F,'Cancels csv'!A:A,'Branch View'!A36,'Cancels csv'!B:B,'Branch View'!B36,'Cancels csv'!D:D,'Branch View'!$I$1) -> 261268.45 | O36: =K36/M36 -> 1.5570033 | P36: =L36/N36 -> 1.5122755
A37: 2024 | B37: 9 | C37: September | D37: =SUMIFS('Sales csv'!E:E,'Sales csv'!A:A,'Branch View'!A37,'Sales csv'!B:B,'Branch View'!B37,'Sales csv'!D:D,'Branch View'!$I$1) -> 87 | E37: =SUMIFS('Sales csv'!F:F,'Sales csv'!A:A,'Branch View'!A37,'Sales csv'!B:B,'Branch View'!B37,'Sales csv'!D:D,'Branch View'!$I$1) -> 76306.67 | F37: =SUMIFS('IM Cancels csv'!$E:$E,'IM Cancels csv'!$A:$A,'Branch View'!$A37,'IM Cancels csv'!$B:$B,'Branch View'!$B37,'IM Cancels csv'!$D:$D,'Branch View'!$I$1) -> 57 | G37: =SUMIFS('IM Cancels csv'!$F:$F,'IM Cancels csv'!$A:$A,'Branch View'!$A37,'IM Cancels csv'!$B:$B,'Branch View'!$B37,'IM Cancels csv'!$D:$D,'Branch View'!$I$1) -> 37839.32 | H37: =D37/F37 -> 1.5263158 | I37: =E37/G37 -> 2.0165973 | K37: =SUMIFS('All Sales csv'!$E:$E,'All Sales csv'!$A:$A,'Branch View'!$A37,'All Sales csv'!$B:$B,'Branch View'!$B37,'All Sales csv'!$D:$D,'Branch View'!$I$1) -> 426 | L37: =SUMIFS('All Sales csv'!$F:$F,'All Sales csv'!$A:$A,'Branch View'!$A37,'All Sales csv'!$B:$B,'Branch View'!$B37,'All Sales csv'!$D:$D,'Branch View'!$I$1) -> 364062.45 | M37: =SUMIFS('Cancels csv'!E:E,'Cancels csv'!A:A,'Branch View'!A37,'Cancels csv'!B:B,'Branch View'!B37,'Cancels csv'!D:D,'Branch View'!$I$1) -> 276 | N37: =SUMIFS('Cancels csv'!F:F,'Cancels csv'!A:A,'Branch View'!A37,'Cancels csv'!B:B,'Branch View'!B37,'Cancels csv'!D:D,'Branch View'!$I$1) -> 221961.54 | O37: =K37/M37 -> 1.5434783 | P37: =L37/N37 -> 1.6402051
A38: 2024 | B38: 10 | C38: October | D38: =SUMIFS('Sales csv'!E:E,'Sales csv'!A:A,'Branch View'!A38,'Sales csv'!B:B,'Branch View'!B38,'Sales csv'!D:D,'Branch View'!$I$1) -> 46 | E38: =SUMIFS('Sales csv'!F:F,'Sales csv'!A:A,'Branch View'!A38,'Sales csv'!B:B,'Branch View'!B38,'Sales csv'!D:D,'Branch View'!$I$1) -> 41145.21 | F38: =SUMIFS('IM Cancels csv'!$E:$E,'IM Cancels csv'!$A:$A,'Branch View'!$A38,'IM Cancels csv'!$B:$B,'Branch View'!$B38,'IM Cancels csv'!$D:$D,'Branch View'!$I$1) -> 49 | G38: =SUMIFS('IM Cancels csv'!$F:$F,'IM Cancels csv'!$A:$A,'Branch View'!$A38,'IM Cancels csv'!$B:$B,'Branch View'!$B38,'IM Cancels csv'!$D:$D,'Branch View'!$I$1) -> 37521.19 | H38: =D38/F38 -> 0.93877551 | I38: =E38/G38 -> 1.096586 | K38: =SUMIFS('All Sales csv'!$E:$E,'All Sales csv'!$A:$A,'Branch View'!$A38,'All Sales csv'!$B:$B,'Branch View'!$B38,'All Sales csv'!$D:$D,'Branch View'!$I$1) -> 108 | L38: =SUMIFS('All Sales csv'!$F:$F,'All Sales csv'!$A:$A,'Branch View'!$A38,'All Sales csv'!$B:$B,'Branch View'!$B38,'All Sales csv'!$D:$D,'Branch View'!$I$1) -> 102765.22 | M38: =SUMIFS('Cancels csv'!E:E,'Cancels csv'!A:A,'Branch View'!A38,'Cancels csv'!B:B,'Branch View'!B38,'Cancels csv'!D:D,'Branch View'!$I$1) -> 202 | N38: =SUMIFS('Cancels csv'!F:F,'Cancels csv'!A:A,'Branch View'!A38,'Cancels csv'!B:B,'Branch View'!B38,'Cancels csv'!D:D,'Branch View'!$I$1) -> 169604.87 | O38: =K38/M38 -> 0.53465347 | P38: =L38/N38 -> 0.60590961
A39: 2024 | B39: 11 | C39: November | D39: =SUMIFS('Sales csv'!E:E,'Sales csv'!A:A,'Branch View'!A39,'Sales csv'!B:B,'Branch View'!B39,'Sales csv'!D:D,'Branch View'!$I$1) -> 31 | E39: =SUMIFS('Sales csv'!F:F,'Sales csv'!A:A,'Branch View'!A39,'Sales csv'!B:B,'Branch View'!B39,'Sales csv'!D:D,'Branch View'!$I$1) -> 28397.52 | F39: =SUMIFS('IM Cancels csv'!$E:$E,'IM Cancels csv'!$A:$A,'Branch View'!$A39,'IM Cancels csv'!$B:$B,'Branch View'!$B39,'IM Cancels csv'!$D:$D,'Branch View'!$I$1) -> 23 | G39: =SUMIFS('IM Cancels csv'!$F:$F,'IM Cancels csv'!$A:$A,'Branch View'!$A39,'IM Cancels csv'!$B:$B,'Branch View'!$B39,'IM Cancels csv'!$D:$D,'Branch View'!$I$1) -> 17136.19 | H39: =D39/F39 -> 1.3478261 | I39: =E39/G39 -> 1.6571665 | K39: =SUMIFS('All Sales csv'!$E:$E,'All Sales csv'!$A:$A,'Branch View'!$A39,'All Sales csv'!$B:$B,'Branch View'!$B39,'All Sales csv'!$D:$D,'Branch View'!$I$1) -> 76 | L39: =SUMIFS('All Sales csv'!$F:$F,'All Sales csv'!$A:$A,'Branch View'!$A39,'All Sales csv'!$B:$B,'Branch View'!$B39,'All Sales csv'!$D:$D,'Branch View'!$I$1) -> 71601.35 | M39: =SUMIFS('Cancels csv'!E:E,'Cancels csv'!A:A,'Branch View'!A39,'Cancels csv'!B:B,'Branch View'!B39,'Cancels csv'!D:D,'Branch View'!$I$1) -> 155 | N39: =SUMIFS('Cancels csv'!F:F,'Cancels csv'!A:A,'Branch View'!A39,'Cancels csv'!B:B,'Branch View'!B39,'Cancels csv'!D:D,'Branch View'!$I$1) -> 135420.21 | O39: =K39/M39 -> 0.49032258 | P39: =L39/N39 -> 0.5287346
A40: 2024 | B40: 12 | C40: December | D40: =SUMIFS('Sales csv'!E:E,'Sales csv'!A:A,'Branch View'!A40,'Sales csv'!B:B,'Branch View'!B40,'Sales csv'!D:D,'Branch View'!$I$1) -> 16 | E40: =SUMIFS('Sales csv'!F:F,'Sales csv'!A:A,'Branch View'!A40,'Sales csv'!B:B,'Branch View'!B40,'Sales csv'!D:D,'Branch View'!$I$1) -> 16214.33 | F40: =SUMIFS('IM Cancels csv'!$E:$E,'IM Cancels csv'!$A:$A,'Branch View'!$A40,'IM Cancels csv'!$B:$B,'Branch View'!$B40,'IM Cancels csv'!$D:$D,'Branch View'!$I$1) -> 36 | G40: =SUMIFS('IM Cancels csv'!$F:$F,'IM Cancels csv'!$A:$A,'Branch View'!$A40,'IM Cancels csv'!$B:$B,'Branch View'!$B40,'IM Cancels csv'!$D:$D,'Branch View'!$I$1) -> 29869.47 | H40: =D40/F40 -> 0.44444444 | I40: =E40/G40 -> 0.54283956 | K40: =SUMIFS('All Sales csv'!$E:$E,'All Sales csv'!$A:$A,'Branch View'!$A40,'All Sales csv'!$B:$B,'Branch View'!$B40,'All Sales csv'!$D:$D,'Branch View'!$I$1) -> 26 | L40: =SUMIFS('All Sales csv'!$F:$F,'All Sales csv'!$A:$A,'Branch View'!$A40,'All Sales csv'!$B:$B,'Branch View'!$B40,'All Sales csv'!$D:$D,'Branch View'!$I$1) -> 25338.07 | M40: =SUMIFS('Cancels csv'!E:E,'Cancels csv'!A:A,'Branch View'!A40,'Cancels csv'!B:B,'Branch View'!B40,'Cancels csv'!D:D,'Branch View'!$I$1) -> 214 | N40: =SUMIFS('Cancels csv'!F:F,'Cancels csv'!A:A,'Branch View'!A40,'Cancels csv'!B:B,'Branch View'!B40,'Cancels csv'!D:D,'Branch View'!$I$1) -> 192292.68 | O40: =K40/M40 -> 0.12149533 | P40: =L40/N40 -> 0.13176825
...

Sheet YOY 2 Branch
A1: Choose branch1: | B1: Lexington - KY | C1: Branch1
A2: Choose branch2: | B2: Dallas Fort Worth Northwest - TX | C2: Branch2
A3: Year | B3: Sales | D3: Sales CV | F3: IM Cancels | J3: IM Sales / IM Cancels | L3: IM Sales CV / IM Cancels CV
A4: {=_xlfn.UNIQUE('Branch View'!A:A)} -> 0 | B4: =_xlfn.CONCAT("IM Sales ",IF(ISBLANK(B1),C1,B1)) -> IM Sales Lexington - KY | C4: =_xlfn.CONCAT("IM Sales ",IF(ISBLANK(B2),C2,B2)) -> IM Sales Dallas Fort Worth Northwest - TX | D4: =_xlfn.CONCAT("Sales CV ",IF(ISBLANK(B1),C1,B1)) -> Sales CV Lexington - KY | E4: =_xlfn.CONCAT("Sales CV ",IF(ISBLANK(B2),C2,B2)) -> Sales CV Dallas Fort Worth Northwest - TX | F4: =_xlfn.CONCAT("IM Cancels ",IF(ISBLANK(B1),C1,B1)) -> IM Cancels Lexington - KY | G4: =_xlfn.CONCAT("IM Cancels ",IF(ISBLANK(B2),C2,B2)) -> IM Cancels Dallas Fort Worth Northwest - TX | H4: =_xlfn.CONCAT("IM Cancels CV ",B1) -> IM Cancels CV Lexington - KY | I4: =_xlfn.CONCAT("IM Cancels CV ",B2) -> IM Cancels CV Dallas Fort Worth Northwest - TX | J4: =_xlfn.CONCAT("IM Sales / IM Cancels ",B1) -> IM Sales / IM Cancels Lexington - KY | K4: =_xlfn.CONCAT("IM Sales / IM Cancels ",B2) -> IM Sales / IM Cancels Dallas Fort Worth Northwest - TX | L4: =_xlfn.CONCAT("IM Sales CV / IM Cancels CV ",B1) -> IM Sales CV / IM Cancels CV Lexington - KY | M4: =_xlfn.CONCAT("IM Sales CV / IM Cancels CV ",B2) -> IM Sales CV / IM Cancels CV Dallas Fort Worth Northwest - TX | O4: =_xlfn.CONCAT("Cancels ",IF(ISBLANK(B1),C1,B1)) -> Cancels Lexington - KY | P4: =_xlfn.CONCAT("Cancels ",IF(ISBLANK(B2),C2,B2)) -> Cancels Dallas Fort Worth Northwest - TX | Q4: =_xlfn.CONCAT("Cancels CV ",IF(ISBLANK(B1),C1,B1)) -> Cancels CV Lexington - KY | R4: =_xlfn.CONCAT("Cancels CV ",IF(ISBLANK(B2),C2,B2)) -> Cancels CV Dallas Fort Worth Northwest - TX | S4: =_xlfn.CONCAT("Sales/Cancels ",IF(ISBLANK(B1),C1,B1)) -> Sales/Cancels Lexington - KY | T4: =_xlfn.CONCAT("Sales/Cancels ",IF(ISBLANK(B2),C2,B2)) -> Sales/Cancels Dallas Fort Worth Northwest - TX | U4: =_xlfn.CONCAT("Sale CV / Cancel CV ",IF(ISBLANK(B1),C1,B1)) -> Sale CV / Cancel CV Lexington - KY | V4: =_xlfn.CONCAT("Sale CV / Cancel CV ",IF(ISBLANK(B2),C2,B2)) -> Sale CV / Cancel CV Dallas Fort Worth Northwest - TX
A5: Year
A6: 2022 | B6: =SUMIFS('Sales csv'!E:E,'Sales csv'!A:A,'YOY 2 Branch'!A6,'Sales csv'!D:D,'YOY 2 Branch'!$B$1) -> 1249 | C6: =SUMIFS('Sales csv'!E:E,'Sales csv'!A:A,'YOY 2 Branch'!A6,'Sales csv'!D:D,'YOY 2 Branch'!$B$2) -> 279 | D6: =SUMIFS('Sales csv'!F:F,'Sales csv'!A:A,'YOY 2 Branch'!A6,'Sales csv'!D:D,'YOY 2 Branch'!$B$1) -> 917063.49 | E6: =SUMIFS('Sales csv'!F:F,'Sales csv'!A:A,'YOY 2 Branch'!A6,'Sales csv'!D:D,'YOY 2 Branch'!$B$2) -> 197409.49 | F6: =SUMIFS('IM Cancels csv'!E:E,'IM Cancels csv'!D:D,'YOY 2 Branch'!$B$1,'IM Cancels csv'!A:A,'YOY 2 Branch'!A6) -> 876 | G6: =SUMIFS('IM Cancels csv'!E:E,'IM Cancels csv'!D:D,'YOY 2 Branch'!$B$2,'IM Cancels csv'!A:A,'YOY 2 Branch'!A6) -> 106 | H6: =SUMIFS('IM Cancels csv'!F:F,'IM Cancels csv'!A:A,'YOY 2 Branch'!A6,'IM Cancels csv'!D:D,'YOY 2 Branch'!$B$1) -> 546660.54 | I6: =SUMIFS('IM Cancels csv'!F:F,'IM Cancels csv'!A:A,'YOY 2 Branch'!A6,'IM Cancels csv'!D:D,'YOY 2 Branch'!$B$2) -> 53986.44 | J6: =B6/F6 -> 1.4257991 | K6: =C6/G6 -> 2.6320755 | L6: =D6/H6 -> 1.677574 | M6: =E6/I6 -> 3.6566495 | O6: =SUMIFS('Cancels csv'!E:E,'Cancels csv'!A:A,'YOY 2 Branch'!A6,'Cancels csv'!D:D,'YOY 2 Branch'!$B$1) -> 2705 | P6: =SUMIFS('Cancels csv'!E:E,'Cancels csv'!A:A,'YOY 2 Branch'!A6,'Cancels csv'!D:D,'YOY 2 Branch'!$B$2) -> 1399 | Q6: =SUMIFS('Cancels csv'!F:F,'Cancels csv'!A:A,'YOY 2 Branch'!A6,'Cancels csv'!D:D,'YOY 2 Branch'!$B$1) -> 1546093.4 | R6: =SUMIFS('Cancels csv'!F:F,'Cancels csv'!A:A,'YOY 2 Branch'!A6,'Cancels csv'!D:D,'YOY 2 Branch'!$B$2) -> 646125.39 | S6: =B6/O6 -> 0.46173752 | T6: =C6/P6 -> 0.19942816 | U6: =D6/Q6 -> 0.59314881 | V6: =E6/R6 -> 0.30552814
A7: 2023 | B7: =SUMIFS('Sales csv'!E:E,'Sales csv'!A:A,'YOY 2 Branch'!A7,'Sales csv'!D:D,'YOY 2 Branch'!$B$1) -> 809 | C7: =SUMIFS('Sales csv'!E:E,'Sales csv'!A:A,'YOY 2 Branch'!A7,'Sales csv'!D:D,'YOY 2 Branch'!$B$2) -> 313 | D7: =SUMIFS('Sales csv'!F:F,'Sales csv'!A:A,'YOY 2 Branch'!A7,'Sales csv'!D:D,'YOY 2 Branch'!$B$1) -> 649748.71 | E7: =SUMIFS('Sales csv'!F:F,'Sales csv'!A:A,'YOY 2 Branch'!A7,'Sales csv'!D:D,'YOY 2 Branch'!$B$2) -> 238834.5 | F7: =SUMIFS('IM Cancels csv'!E:E,'IM Cancels csv'!D:D,'YOY 2 Branch'!$B$1,'IM Cancels csv'!A:A,'YOY 2 Branch'!A7) -> 1005 | G7: =SUMIFS('IM Cancels csv'!E:E,'IM Cancels csv'!D:D,'YOY 2 Branch'!$B$2,'IM Cancels csv'!A:A,'YOY 2 Branch'!A7) -> 170 | H7: =SUMIFS('IM Cancels csv'!F:F,'IM Cancels csv'!A:A,'YOY 2 Branch'!A7,'IM Cancels csv'!D:D,'YOY 2 Branch'!$B$1) -> 716705.41 | I7: =SUMIFS('IM Cancels csv'!F:F,'IM Cancels csv'!A:A,'YOY 2 Branch'!A7,'IM Cancels csv'!D:D,'YOY 2 Branch'!$B$2) -> 120330.09 | J7: =B7/F7 -> 0.80497512 | K7: =C7/G7 -> 1.8411765 | L7: =D7/H7 -> 0.9065771 | M7: =E7/I7 -> 1.9848277 | O7: =SUMIFS('Cancels csv'!E:E,'Cancels csv'!A:A,'YOY 2 Branch'!A7,'Cancels csv'!D:D,'YOY 2 Branch'!$B$1) -> 2756 | P7: =SUMIFS('Cancels csv'!E:E,'Cancels csv'!A:A,'YOY 2 Branch'!A7,'Cancels csv'!D:D,'YOY 2 Branch'!$B$2) -> 1191 | Q7: =SUMIFS('Cancels csv'!F:F,'Cancels csv'!A:A,'YOY 2 Branch'!A7,'Cancels csv'!D:D,'YOY 2 Branch'!$B$1) -> 1819318.7 | R7: =SUMIFS('Cancels csv'!F:F,'Cancels csv'!A:A,'YOY 2 Branch'!A7,'Cancels csv'!D:D,'YOY 2 Branch'!$B$2) -> 696920.12 | S7: =B7/O7 -> 0.29354136 | T7: =C7/P7 -> 0.26280437 | U7: =D7/Q7 -> 0.35713847 | V7: =E7/R7 -> 0.34269996
A8: 2024 | B8: =SUMIFS('Sales csv'!E:E,'Sales csv'!A:A,'YOY 2 Branch'!A8,'Sales csv'!D:D,'YOY 2 Branch'!$B$1) -> 819 | C8: =SUMIFS('Sales csv'!E:E,'Sales csv'!A:A,'YOY 2 Branch'!A8,'Sales csv'!D:D,'YOY 2 Branch'!$B$2) -> 368 | D8: =SUMIFS('Sales csv'!F:F,'Sales csv'!A:A,'YOY 2 Branch'!A8,'Sales csv'!D:D,'YOY 2 Branch'!$B$1) -> 670620.37 | E8: =SUMIFS('Sales csv'!F:F,'Sales csv'!A:A,'YOY 2 Branch'!A8,'Sales csv'!D:D,'YOY 2 Branch'!$B$2) -> 300951.17 | F8: =SUMIFS('IM Cancels csv'!E:E,'IM Cancels csv'!D:D,'YOY 2 Branch'!$B$1,'IM Cancels csv'!A:A,'YOY 2 Branch'!A8) -> 786 | G8: =SUMIFS('IM Cancels csv'!E:E,'IM Cancels csv'!D:D,'YOY 2 Branch'!$B$2,'IM Cancels csv'!A:A,'YOY 2 Branch'!A8) -> 182 | H8: =SUMIFS('IM Cancels csv'!F:F,'IM Cancels csv'!A:A,'YOY 2 Branch'!A8,'IM Cancels csv'!D:D,'YOY 2 Branch'!$B$1) -> 590823.22 | I8: =SUMIFS('IM Cancels csv'!F:F,'IM Cancels csv'!A:A,'YOY 2 Branch'!A8,'IM Cancels csv'!D:D,'YOY 2 Branch'!$B$2) -> 145835.54 | J8: =B8/F8 -> 1.0419847 | K8: =C8/G8 -> 2.021978 | L8: =D8/H8 -> 1.135061 | M8: =E8/I8 -> 2.0636339 | O8: =SUMIFS('Cancels csv'!E:E,'Cancels csv'!A:A,'YOY 2 Branch'!A8,'Cancels csv'!D:D,'YOY 2 Branch'!$B$1) -> 2066 | P8: =SUMIFS('Cancels csv'!E:E,'Cancels csv'!A:A,'YOY 2 Branch'!A8,'Cancels csv'!D:D,'YOY 2 Branch'!$B$2) -> 836 | Q8: =SUMIFS('Cancels csv'!F:F,'Cancels csv'!A:A,'YOY 2 Branch'!A8,'Cancels csv'!D:D,'YOY 2 Branch'!$B$1) -> 1476471.9 | R8: =SUMIFS('Cancels csv'!F:F,'Cancels csv'!A:A,'YOY 2 Branch'!A8,'Cancels csv'!D:D,'YOY 2 Branch'!$B$2) -> 537697.92 | S8: =B8/O8 -> 0.3964182 | T8: =C8/P8 -> 0.44019139 | U8: =D8/Q8 -> 0.45420462 | V8: =E8/R8 -> 0.55970306
