Workbook

Sheet Summary & Conclusion
B1: ='Orlando Spend And Close Rate'!I1 -> Leads | C1: ='Orlando Spend And Close Rate'!J1 -> Sales | D1: ='Orlando Spend And Close Rate'!K1 -> Close rate | E1: ='Orlando Spend And Close Rate'!L1 -> Contract Value | F1: ='Orlando Spend And Close Rate'!M1 -> Spend | G1: ='Orlando Spend And Close Rate'!N1 -> ROI (Contract Value minus spend divided by spend)
A2: ='Orlando Spend And Close Rate'!H2 -> Avg Incl Orlando | B2: ='Orlando Spend And Close Rate'!I2 -> 2054.9762 | C2: ='Orlando Spend And Close Rate'!J2 -> 780.35714 | D2: ='Orlando Spend And Close Rate'!K2 -> 0.36272143 | E2: ='Orlando Spend And Close Rate'!L2 -> 763991.76 | F2: ='Orlando Spend And Close Rate'!M2 -> 171339.21 | G2: ='Orlando Spend And Close Rate'!N2 -> 3.458943
A3: ='Orlando Spend And Close Rate'!H3 -> Avg Excl Orlando | B3: ='Orlando Spend And Close Rate'!I3 -> 2076.9268 | C3: ='Orlando Spend And Close Rate'!J3 -> 790.2439 | D3: ='Orlando Spend And Close Rate'!K3 -> 0.36364878 | E3: ='Orlando Spend And Close Rate'!L3 -> 775073.54 | F3: ='Orlando Spend And Close Rate'!M3 -> 171245.93 | G3: ='Orlando Spend And Close Rate'!N3 -> 3.5260845
A5: ='Orlando Spend And Close Rate'!H5 -> Median Incl Orlando | B5: ='Orlando Spend And Close Rate'!I5 -> 1710.5 | C5: ='Orlando Spend And Close Rate'!J5 -> 603 | D5: ='Orlando Spend And Close Rate'!K5 -> 0.3651 | E5: ='Orlando Spend And Close Rate'!L5 -> 581903.75 | F5: ='Orlando Spend And Close Rate'!M5 -> 161456 | G5: ='Orlando Spend And Close Rate'!N5 -> 2.6041011
A6: ='Orlando Spend And Close Rate'!H6 -> Median Excl Orlando | B6: ='Orlando Spend And Close Rate'!I6 -> 1724 | C6: ='Orlando Spend And Close Rate'!J6 -> 617 | D6: ='Orlando Spend And Close Rate'!K6 -> 0.3655 | E6: ='Orlando Spend And Close Rate'!L6 -> 595648.5 | F6: ='Orlando Spend And Close Rate'!M6 -> 149166.5 | G6: ='Orlando Spend And Close Rate'!N6 -> 2.9931788
A8: ='Orlando Spend And Close Rate'!H8 -> Actual Orlando | B8: ='Orlando Spend And Close Rate'!I8 -> 1155 | C8: ='Orlando Spend And Close Rate'!J8 -> 375 | D8: ='Orlando Spend And Close Rate'!K8 -> 0.3247 | E8: ='Orlando Spend And Close Rate'!L8 -> 309639 | F8: ='Orlando Spend And Close Rate'!M8 -> 173951 | G8: ='Orlando Spend And Close Rate'!N8 -> 0.78003576
A10: ='Orlando Spend And Close Rate'!H10 -> Conclusion:
A11: ='Orlando Spend And Close Rate'!H11 -> Orlando is bringing down the company average and median in leads, sales, contract value and ROI while increasing the average and median company spend

Sheet Branch Spend
A1: Branch | B1: Google Ads | C1: LSA | D1: Bing | E1: Goodzer | F1: LBC | G1: PestNet | H1: eLocal | I1: Meta | J1: RingLocal | K1: Con Affairs | L1: Aragon | M1: Service Direct | N1: Baton | O1: Lead Prediction | P1: Abstrakt | Q1: Yelp | R1: Total | S1: Column1 | T1: Baton Raw | U1: _1
A2: Albany | B2: 40771 | C2: 33542 | D2: 5272 | E2: 1850 | F2: 3036 | G2: 8707 | H2: 6055 | I2: 67 | J2: 528 | K2: 1657 | L2: 1525 | M2: 4630 | N2: $1,131 | O2: 3312 | P2: 724 | Q2: 345 | R2: $113,153 | T2: 6676
A3: Baton Rouge | B3: 36130 | C3: 44523 | D3: 1606 | E3: 2540 | F3: 3036 | G3: 8707 | H3: 3325 | I3: 67 | J3: 528 | K3: 1657 | L3: 1525 | M3: 340 | N3: $299 | O3: 3312 | P3: 724 | Q3: 345 | R3: $108,663 | T3: 1764
A4: CT | B4: 182206 | C4: 226155 | D4: 14923 | E4: 8910 | F4: 6072 | G4: 17414 | H4: 43105 | I4: 135 | J4: 1056 | K4: 3313 | L4: 3049 | M4: 15985 | N4: $4,152 | O4: 6625 | P4: 1448 | Q4: 690 | R4: 530666 | S4: $- | T4: 24501
A5: Bloomington | B5: 26964 | C5: 8672 | D5: 4482 | E5: 2240 | F5: 3036 | G5: 8707 | H5: 9180 | I5: 67 | J5: 528 | K5: 1657 | L5: 1525 | M5: 820 | N5: $288 | O5: 3312 | P5: 724 | Q5: 345 | R5: $72,547 | T5: 1697
A6: Boston | B6: 149714 | C6: 88958 | D6: 9967 | E6: 2465 | F6: 3036 | G6: 8707 | H6: 12900 | I6: 67 | J6: 528 | K6: 1657 | L6: 1525 | M6: 2650 | N6: $1,749 | O6: 3312 | P6: 724 | Q6: 345 | R6: $288,304 | T6: 10319
A7: Buffalo | B7: 78712 | C7: 104342 | D7: 5272 | E7: 3650 | F7: 3036 | G7: 8707 | H7: 18455 | I7: 67 | J7: 528 | K7: 1657 | L7: 1525 | M7: 3000 | N7: $589 | O7: 3312 | P7: 724 | Q7: 345 | R7: $233,923 | T7: 3478
A8: Central NJ | B8: 44281 | C8: 48405 | D8: 5311 | E8: 825 | F8: 3036 | G8: 8707 | H8: 3510 | I8: 67 | J8: 528 | K8: 1657 | L8: 1525 | M8: 750 | N8: $3,644 | O8: 3312 | P8: 724 | Q8: 345 | R8: $126,627 | T8: 21505
A9: Chicago | B9: 248799 | C9: 75312 | D9: 13445 | E9: 2500 | F9: 6072 | G9: 17414 | H9: 21230 | I9: 135 | J9: 1056 | K9: 3313 | L9: 3049 | M9: 5205 | N9: $10,225 | O9: 6625 | P9: 1448 | Q9: 690 | R9: $413,426 | S9: $- | T9: 60341
A10: Corpus Christi | B10: 28907 | C10: 45281 | D10: 1537.59 | E10: 2010 | F10: 3036 | G10: 8707 | H10: 3680 | I10: 67 | J10: 528 | K10: 1657 | L10: 1525 | M10: 806 | N10: $179 | O10: 3312 | P10: 724 | Q10: 345 | R10: $102,302 | T10: 1056
A11: Dallas Fort Worth | B11: 71889 | C11: 16528 | D11: 1537.59 | E11: 910 | F11: 3036 | G11: 8707 | H11: 560 | I11: 67 | J11: 528 | K11: 1657 | L11: 1525 | N11: $1,806 | O11: 3312 | P11: 724 | Q11: 345 | R11: $113,132 | T11: 10660
A12: Harrisburg | B12: 137042.04 | C12: 94979 | D12: 9725 | E12: 5970 | F12: 3036 | G12: 8707 | H12: 9230 | I12: 67 | J12: 528 | K12: 1657 | L12: 1525 | M12: 5760 | N12: $5,508 | O12: 3312 | P12: 724 | Q12: 345 | R12: $288,115 | T12: 32505
A13: Hudson Valley | B13: 176628 | C13: 64266 | D13: 5272 | E13: 2990 | F13: 3036 | G13: 8707 | H13: 14995 | I13: 67 | J13: 528 | K13: 1657 | L13: 1525 | M13: 9165 | N13: $2,654 | O13: 3312 | P13: 724 | Q13: 345 | R13: $295,870 | T13: 15659
A14: Lafayette | B14: 33242 | C14: 13896 | D14: 1606 | E14: 2335 | F14: 3036 | G14: 8707 | H14: 4715 | I14: 67 | J14: 528 | K14: 1657 | L14: 1525 | M14: 155 | N14: $91 | O14: 3312 | P14: 724 | Q14: 345 | R14: $75,940 | T14: 536
A15: Lexington | B15: 36734 | C15: 41556 | D15: 3944 | E15: 1555 | F15: 3036 | G15: 8707 | H15: 3390 | I15: 67 | J15: 528 | K15: 1657 | L15: 1525 | M15: 440 | N15: $- | O15: 3312 | P15: 724 | Q15: 345 | R15: $107,520
A16: Lubbock | B16: 21152 | C16: 47576 | D16: 1537.59 | E16: 2635 | F16: 3036 | G16: 8707 | H16: 1445 | I16: 67 | J16: 528 | K16: 1657 | L16: 1525 | M16: 420 | N16: $379 | O16: 3312 | P16: 724 | Q16: 345 | R16: $95,046 | T16: 2237
A17: Manchester | B17: 149714 | C17: 57237 | D17: 4656 | E17: 1900 | F17: 3036 | G17: 8707 | H17: 3505 | I17: 67 | J17: 528 | K17: 1657 | L17: 1525 | M17: 1600 | N17: $690 | O17: 3312 | P17: 724 | Q17: 345 | R17: $239,204 | T17: 4074
A18: McAllen (Pharr) | B18: 30278 | C18: 51439 | D18: 1537.59 | E18: 4025 | F18: 3036 | G18: 8707 | H18: 7640 | I18: 67 | J18: 528 | K18: 1657 | L18: 1525 | M18: 1065 | N18: $255 | O18: 3312 | P18: 724 | Q18: 345 | R18: $116,141 | T18: 1505
A19: Midland | B19: 26146 | C19: 41418 | D19: 1537.59 | E19: 580 | F19: 3036 | G19: 8707 | H19: 2585 | I19: 67 | J19: 528 | K19: 1657 | L19: 1525 | M19: 55 | N19: $102 | O19: 3312 | P19: 724 | Q19: 345 | R19: $92,325 | T19: 600
A20: North Shore | B20: 15337 | C20: 10283 | D20: 1606 | E20: 1525 | F20: 3036 | G20: 8707 | H20: 1545 | I20: 67 | J20: 528 | K20: 1657 | L20: 1525 | M20: 165 | N20: $109 | O20: 3312 | P20: 724 | Q20: 345 | R20: $50,471 | T20: 646
A21: Northern VA | B21: 61142 | C21: 14242 | D21: 2191 | E21: 1715 | F21: 3036 | G21: 8707 | H21: 9725 | I21: 67 | J21: 528 | K21: 1657 | L21: 1525 | M21: 1745 | N21: $3,936 | O21: 3312 | P21: 724 | Q21: 345 | R21: $114,597 | T21: 23229
A22: NY - Long Island | B22: 176579 | C22: 79860 | D22: 5272 | E22: 5900 | F22: 3036 | G22: 8707 | H22: 12910 | I22: 67 | J22: 528 | K22: 1657 | L22: 1525 | M22: 1915 | N22: $1,747 | O22: 3312 | P22: 724 | Q22: 345 | R22: $304,085 | T22: 10312
A23: Orlando | B23: 96190 | C23: 42481 | D23: 6147 | E23: 3835 | F23: 3036 | G23: 8707 | H23: 3020 | I23: 67 | J23: 528 | K23: 1657 | L23: 1525 | M23: 1545 | N23: $832 | O23: 3312 | P23: 724 | Q23: 345 | R23: $173,951 | T23: 4907
A24: Pittsburgh | B24: 97088 | C24: 37427 | D24: 7561 | E24: 955 | F24: 3036 | G24: 8707 | H24: 7175 | I24: 67 | J24: 528 | K24: 1657 | L24: 1525 | M24: 3000 | N24: $4,071 | O24: 3312 | P24: 724 | Q24: 345 | R24: $177,179 | T24: 24025
A25: Rhode Island | B25: 100200 | C25: 63824 | D25: 13515 | E25: 3590 | F25: 3036 | G25: 8707 | H25: 33060 | I25: 67 | J25: 528 | K25: 1657 | L25: 1525 | M25: 9970 | N25: $3,013 | O25: 3312 | P25: 724 | Q25: 345 | R25: $247,072 | T25: 17780
A26: Rochester | B26: 58121 | C26: 62540 | D26: 5272 | E26: 1940 | F26: 3036 | G26: 8707 | H26: 11135 | I26: 67 | J26: 528 | K26: 1657 | L26: 1525 | M26: 2190 | N26: $357 | O26: 3312 | P26: 724 | Q26: 345 | R26: $161,456 | T26: 2105
A27: Syracuse | B27: 44646 | C27: 46816 | D27: 5272 | E27: 5050 | F27: 3036 | G27: 8707 | H27: 11745 | I27: 67 | J27: 528 | K27: 1657 | L27: 1525 | M27: 2915 | N27: $532 | O27: 3312 | P27: 724 | Q27: 345 | R27: $136,877 | T27: 3138
A28: Virginia Beach | B28: 103437 | C28: 43980 | D28: 13071 | E28: 1380 | F28: 3036 | G28: 8707 | H28: 4650 | I28: 67 | J28: 528 | K28: 1657 | L28: 1525 | M28: 2165 | N28: $1,661 | O28: 3312 | P28: 724 | Q28: 345 | R28: $190,245 | T28: 9804
A29: Unattributed | R29: $-
A30: Total | B30: 2272049 | C30: 1505540 | D30: 153076 | E30: 75780 | F30: 88050 | G30: 252500 | H30: 264470 | I30: 1953 | J30: 15315 | K30: 48040 | L30: 44215 | M30: 78456 | N30: $50,000 | O30: 96056 | P30: 21000 | Q30: 10000 | R30: $4,976,499 | T30: 295059

Sheet Orlando Spend And Close Rate
A1: Branch | B1: Year | C1: Leads | D1: Sales | E1: Close Rate (Sales/Leads) | F1: Contract Value | G1: Spend | I1: Leads | J1: Sales | K1: Close rate | L1: Contract Value | M1: Spend | N1: ROI (Contract Value minus spend divided by spend)
A2: NULL | B2: 2025 | C2: 12820 | D2: 0 | E2: 0 | F2: NULL | H2: Avg Incl Orlando | I2: =AVERAGE(C3:C44) -> 2054.9762 | J2: =AVERAGE(D3:D44) -> 780.35714 | K2: =AVERAGE(E3:E44) -> 0.36272143 | L2: =AVERAGE(F3:F44) -> 763991.76 | M2: =AVERAGE(G3:G44) -> 171339.21 | N2: =(L2-M2)/M2 -> 3.458943
A3: Albany - NY | B3: 2025 | C3: 1724 | D3: 724 | E3: 0.42 | F3: =707824.27 -> 707824.27 | G3: =113153 -> 113153 | H3: Avg Excl Orlando | I3: =AVERAGE(C3:C29,C31:C44) -> 2076.9268 | J3: =AVERAGE(D3:D29,D31:D44) -> 790.2439 | K3: =AVERAGE(E3:E29,E31:E44) -> 0.36364878 | L3: =AVERAGE(F3:F29,F31:F44) -> 775073.54 | M3: =AVERAGE(G3:G29,G31:G44) -> 171245.93 | N3: =(L3-M3)/M3 -> 3.5260845
A4: Baton Rouge - LA | B4: 2025 | C4: 1697 | D4: 564 | E4: 0.3324 | F4: =489151.78 -> 489151.78 | G4: =108663 -> 108663
A5: Bloomington - IL | B5: 2025 | C5: 708 | D5: 259 | E5: 0.3658 | F5: =239120.44 -> 239120.44 | G5: =72547 -> 72547 | H5: Median Incl Orlando | I5: =MEDIAN(C3:C44) -> 1710.5 | J5: =MEDIAN(D3:D44) -> 603 | K5: =MEDIAN(E3:E44) -> 0.3651 | L5: =MEDIAN(F3:F44) -> 581903.75 | M5: =MEDIAN(G3:G44) -> 161456 | N5: =(L5-M5)/M5 -> 2.6041011
A6: Boston - MA | B6: 2025 | C6: 3369 | D6: 1220 | E6: 0.3621 | F6: =1377950.46 -> 1377950.5 | G6: =288304 -> 288304 | H6: Median Excl Orlando | I6: =MEDIAN(C3:C29,C31:C44) -> 1724 | J6: =MEDIAN(D3:D29,D31:D44) -> 617 | K6: =MEDIAN(E3:E29,E31:E44) -> 0.3655 | L6: =MEDIAN(F3:F29,F31:F44) -> 595648.5 | M6: =MEDIAN(G31:G44,G3:G29) -> 149166.5 | N6: =(L6-M6)/M6 -> 2.9931788
A7: Buffalo - NY | B7: 2025 | C7: 2324 | D7: 892 | E7: 0.3838 | F7: =844118.05 -> 844118.05 | G7: =233923 -> 233923
A8: Burlington -VT | B8: 2025 | C8: 256 | D8: 85 | E8: 0.332 | F8: =97955 -> 97955 | H8: Actual Orlando | I8: =C30 -> 1155 | J8: =D30 -> 375 | K8: =E30 -> 0.3247 | L8: =F30 -> 309639 | M8: =G30 -> 173951 | N8: =(L8-M8)/M8 -> 0.78003576
A9: Chicago North - IL | B9: 2025 | C9: 2223 | D9: 793 | E9: 0.3567 | F9: =688330.55 -> 688330.55 | G9: =413426/2 -> 206713
A10: Chicago South - IL | B10: 2025 | C10: 2902 | D10: 960 | E10: 0.3308 | F10: =760691.21 -> 760691.21 | G10: =413426/2 -> 206713 | H10: Conclusion:
A11: Corpus Christi - TX | B11: 2025 | C11: 2242 | D11: 838 | E11: 0.3738 | F11: =668817.89 -> 668817.89 | G11: =102302 -> 102302 | H11: Orlando is bringing down the company average and median in leads, sales, contract value and ROI while increasing the average and median company spend
A12: Dallas Fort Worth Northwest - TX | B12: 2025 | C12: 1162 | D12: 369 | E12: 0.3176 | F12: =312978.42 -> 312978.42 | G12: =113132 -> 113132
A13: DC West - DC | B13: 2025 | C13: 1092 | D13: 327 | E13: 0.2995 | F13: =308748.38 -> 308748.38 | G13: =114597 -> 114597
A14: Evansville - IN | B14: 2025 | C14: 404 | D14: 105 | E14: 0.2599 | F14: =99742 -> 99742
A15: Harrisburg - PA | B15: 2025 | C15: 4781 | D15: 2075 | E15: 0.434 | F15: =1918479.26 -> 1918479.3 | G15: =288115 -> 288115
A16: Hartford - CT | B16: 2025 | C16: 5824 | D16: 2331 | E16: 0.4002 | F16: =2534227.95 -> 2534228 | G16: =530666/2 -> 265333
A17: Iowa City - IA | B17: 2025 | C17: 776 | D17: 291 | E17: 0.375 | F17: =300511.94 -> 300511.94
A18: Kennewick - WA | B18: 2025 | C18: 249 | D18: 91 | E18: 0.3655 | F18: =88091.77 -> 88091.77
A19: Lafayette - LA | B19: 2025 | C19: 1289 | D19: 473 | E19: 0.367 | F19: =373423.94 -> 373423.94 | G19: =75940 -> 75940
A20: Lexington - KY | B20: 2025 | C20: 1824 | D20: 617 | E20: 0.3383 | F20: =623360.76 -> 623360.76 | G20: =107520 -> 107520
A21: Long Island - NY | B21: 2025 | C21: 4001 | D21: 1459 | E21: 0.3647 | F21: =1555056.53 -> 1555056.5 | G21: =304085 -> 304085
A22: Lubbock - TX | B22: 2025 | C22: 1964 | D22: 756 | E22: 0.3849 | F22: =595648.5 -> 595648.5 | G22: =95046 -> 95046
A23: Manchester - NH | B23: 2025 | C23: 2118 | D23: 836 | E23: 0.3947 | F23: =922365.41 -> 922365.41 | G23: =239204 -> 239204
A24: McAllen - TX | B24: 2025 | C24: 2556 | D24: 853 | E24: 0.3337 | F24: =719753.12 -> 719753.12 | G24: =116141 -> 116141
A25: Midland - TX | B25: 2025 | C25: 2951 | D25: 1244 | E25: 0.4216 | F25: =1172173.64 -> 1172173.6 | G25: =92325 -> 92325
A26: New Jersey Central - NJ | B26: 2025 | C26: 1399 | D26: 475 | E26: 0.3395 | F26: =462826.88 -> 462826.88 | G26: =126627 -> 126627
A27: Newport News - VA | B27: 2025 | C27: 1563 | D27: 589 | E27: 0.3768 | F27: =568159 -> 568159
A28: Northshore - LA | B28: 2025 | C28: 760 | D28: 273 | E28: 0.3592 | F28: =251624.79 -> 251624.79 | G28: =50471 -> 50471
A29: Orchard Park - NY | B29: 2025 | C29: 3538 | D29: 1452 | E29: 0.4104 | F29: =1444866.71 -> 1444866.7
A30: Orlando West - FL | B30: 2025 | C30: 1155 | D30: 375 | E30: 0.3247 | F30: =309639 -> 309639 | G30: =173951 -> 173951
A31: Oxford - CT | B31: 2025 | C31: 6862 | D31: 2888 | E31: 0.4209 | F31: =3078791.56 -> 3078791.6 | G31: =530666/2 -> 265333
A32: Pensacola - FL | B32: 2025 | C32: 798 | D32: 230 | E32: 0.2882 | F32: =227298 -> 227298
A33: Pittsburgh - PA | B33: 2025 | C33: 2229 | D33: 807 | E33: 0.362 | F33: =771563.98 -> 771563.98 | G33: =177179 -> 177179
A34: Portland - ME | B34: 2025 | C34: 846 | D34: 327 | E34: 0.3865 | F34: =344877 -> 344877
A35: Providence - RI | B35: 2025 | C35: 6110 | D35: 2429 | E35: 0.3975 | F35: =2563118.62 -> 2563118.6 | G35: =247072 -> 247072
A36: Reno - NV | B36: 2025 | C36: 321 | D36: 109 | E36: 0.3396 | F36: =106477.72 -> 106477.72
A37: Rochester - NY | B37: 2025 | C37: 3262 | D37: 1247 | E37: 0.3823 | F37: =1208923.63 -> 1208923.6 | G37: =161456 -> 161456
A38: Sioux Falls - SD | B38: 2025 | C38: 329 | D38: 112 | E38: 0.3404 | F38: =110511.99 -> 110511.99
A39: South Bend - IN | B39: 2025 | C39: 576 | D39: 180 | E39: 0.3125 | F39: =172196 -> 172196
A40: Spokane - WA | B40: 2025 | C40: 171 | D40: 62 | E40: 0.3626 | F40: =56966.89 -> 56966.89
...
